Workbook

Sheet Summary
A1: Client Rate Comparison 2026 (rates only)
A2: Trips 2 Jan – 30 Sep 2026 · selling price excl. VAT · payment status ignored · haulage and flat trucks only (treated as one); closed-body/canter and Hiab trips excluded
A4: Revenue achieved vs best rate
A5: Revenue achieved: ₦2,391,115,142
A6: Revenue if every trip had been sold at the best (highest) rate on its route: ₦2,569,440,468 — ₦178,325,327 more (+7.5%)
A7: Revenue at the best-paying client’s average rate: ₦2,509,970,801 — ₦118,855,660 more (+5.0%). Detail by client and month: ‘Achieved vs Best Rate’ sheet.
A9: How to read this
A10: Rate level = what a client pays compared with the best-paying client on the same route in the same quarter. 100% = pays the top rate.
A11: Revenue lost = extra revenue if the client had paid the best-paying client’s average rate on those trips.
A13: Key findings
A14: Total revenue lost to lower rates: ₦118.9M (5.0% of 2026 haulage revenue of ₦2.39bn).
A15: Worst on rates: Jamara — pays ~89% of the best rate but, on high volume, costs ₦52.9M (45% of the total).
... A23: Some differences may have reasons not in the trip log (load weight, waiting time, contract terms). Review the largest gaps with each account.

Sheet Achieved vs Best Rate
A1: Revenue achieved vs revenue at the best rate — 2026
A2: Best rate = the highest rate any client paid on the same route and quarter (haulage and flat trucks only). Best client average = the average rate of the best-paying client on that route. Only trips on routes shared by 2+ clients can be repriced.
A4: Headline
B5: Revenue (₦) | C5: Difference vs achieved (₦) | D5: Difference %
A6: Revenue achieved | B6: =C41
A7: Revenue at best rate (highest on route) | B7: =D41 | C7: =E41 | D7: =C7/B6
A8: Revenue at best client average | B8: =G41 | C8: =H41 | D8: =C8/B6
A10: By client
A11: Client | B11: Trips | C11: Revenue achieved (₦) | D11: Revenue at best rate (₦) | E11: Difference (₦) | F11: Difference % | G11: Revenue at best client avg (₦) | H11: Difference (₦) | I11: Difference %
A12: NBL | B12: 355 | C12: 5.766846e+08 | D12: =C12+E12 | E12: 5488758.1 | F12: =IF(C12=0,0,E12/C12) | G12: =C12+H12 | H12: 1058582.5 | I12: =IF(C12=0,0,H12/C12)
A13: Jamara | B13: 252 | C13: 4.7832228e+08 | D13: =C13+E13 | E13: 68525639 | F13: =IF(C13=0,0,E13/C13) | G13: =C13+H13 | H13: 52915476 | I13: =IF(C13=0,0,H13/C13)
A14: MEGA MANU | B14: 126 | C14: 2.4630395e+08 | D14: =C14+E14 | E14: 41530328 | F14: =IF(C14=0,0,E14/C14) | G14: =C14+H14 | H14: 23787322 | I14: =IF(C14=0,0,H14/C14)
A15: SASO | B15: 43 | C15: 1.7476442e+08 | D15: =C15+E15 | E15: 1503255.8 | F15: =IF(C15=0,0,E15/C15) | G15: =C15+H15 | H15: 37209.302 | I15: =IF(C15=0,0,H15/C15)
A16: NATURAL BEAUTY | B16: 34 | C16: 1.2646279e+08 | D16: =C16+E16 | E16: 16911628 | F16: =IF(C16=0,0,E16/C16) | G16: =C16+H16 | H16: 2506976.7 | I16: =IF(C16=0,0,H16/C16)
A17: ORCA DECO LIMITED | B17: 287 | C17: 1.2501978e+08 | D17: =C17+E17 | E17: 0 | F17: =IF(C17=0,0,E17/C17) | G17: =C17+H17 | H17: 0 | I17: =IF(C17=0,0,H17/C17)
A18: AB-INBEV | B18: 46 | C18: 1.1094374e+08 | D18: =C18+E18 | E18: 0 | F18: =IF(C18=0,0,E18/C18) | G18: =C18+H18 | H18: 0 | I18: =IF(C18=0,0,H18/C18)
A19: JUBAILI AGROTEC | B19: 44 | C19: 1.1060117e+08 | D19: =C19+E19 | E19: 6177712.4 | F19: =IF(C19=0,0,E19/C19) | G19: =C19+H19 | H19: 5694126.3 | I19: =IF(C19=0,0,H19/C19)
A20: VENDARA | B20: 24 | C20: 88279070 | D20: =C20+E20 | E20: 6107459.2 | F20: =IF(C20=0,0,E20/C20) | G20: =C20+H20 | H20: 5627459.2 | I20: =IF(C20=0,0,H20/C20)
A21: Lacasera | B21: 69 | C21: 51736810 | D21: =C21+E21 | E21: 14209890 | F21: =IF(C21=0,0,E21/C21) | G21: =C21+H21 | H21: 14209890 | I21: =IF(C21=0,0,H21/C21)
A22: ABBA ABASS | B22: 34 | C22: 48649302 | D22: =C22+E22 | E22: 0 | F22: =IF(C22=0,0,E22/C22) | G22: =C22+H22 | H22: 0 | I22: =IF(C22=0,0,H22/C22)
A23: GIVANAS | B23: 23 | C23: 43741860 | D23: =C23+E23 | E23: 4396778.9 | F23: =IF(C23=0,0,E23/C23) | G23: =C23+H23 | H23: 1373058 | I23: =IF(C23=0,0,H23/C23)
... A40: B2B-ORCA DECO LIMITED (MR LEKAN) | B40: 1 | C40: 350000 | D40: =C40+E40 | E40: 161627.91 | F40: =IF(C40=0,0,E40/C40) | G40: =C40+H40 | H40: 161627.91 | I40: =IF(C40=0,0,H40/C40)
A41: Total | B41: =SUM(B12:B40) | C41: =SUM(C12:C40) | D41: =SUM(D12:D40) | E41: =SUM(E12:E40) | F41: =E41/C41 | G41: =SUM(G12:G40) | H41: =SUM(H12:H40) | I41: =H41/C41
A43: By month
A44: Month | B44: Trips | C44: Revenue achieved (₦) | D44: Revenue at best rate (₦) | E44: Difference (₦) | F44: Difference % | G44: Revenue at best client avg (₦) | H44: Difference (₦) | I44: Difference %
A45: Jan 2026 | B45: 147 | C45: 2.4320157e+08 | D45: =C45+E45 | E45: 28434380 | F45: =E45/C45 | G45: =C45+H45 | H45: 9481184.9 | I45: =H45/C45
A46: Feb 2026 | B46: 170 | C46: 2.0239258e+08 | D46: =C46+E46 | E46: 42478727 | F46: =E46/C46 | G46: =C46+H46 | H46: 21625702 | I46: =H46/C46
A47: Mar 2026 | B47: 199 | C47: 2.5776009e+08 | D47: =C47+E47 | E47: 19708681 | F47: =E47/C47 | G47: =C47+H47 | H47: 7388741.5 | I47: =H47/C47
A48: Apr 2026 | B48: 187 | C48: 2.6254567e+08 | D48: =C48+E48 | E48: 11509064 | F48: =E48/C48 | G48: =C48+H48 | H48: 8857366.1 | I48: =H48/C48
A49: May 2026 | B49: 197 | C49: 2.952948e+08 | D49: =C49+E49 | E49: 12108049 | F49: =E49/C49 | G49: =C49+H49 | H49: 11176353 | I49: =H49/C49
A50: Jun 2026 | B50: 162 | C50: 3.3031219e+08 | D50: =C50+E50 | E50: 13146977 | F50: =E50/C50 | G50: =C50+H50 | H50: 13418276 | I50: =H50/C50
A51: Jul 2026 | B51: 126 | C51: 2.595201e+08 | D51: =C51+E51 | E51: 16103927 | F51: =E51/C51 | G51: =C51+H51 | H51: 15813362 | I51: =H51/C51
A52: Aug 2026 | B52: 121 | C52: 2.651464e+08 | D52: =C52+E52 | E52: 20493000 | F52: =E52/C52 | G52: =C52+H52 | H52: 16229127 | I52: =H52/C52
A53: Sep 2026 | B53: 124 | C53: 2.7494174e+08 | D53: =C53+E53 | E53: 14342522 | F53: =E53/C53 | G53: =C53+H53 | H53: 14865547 | I53: =H53/C53
A54: Total | B54: =SUM(B45:B53) | C54: =SUM(C45:C53) | D54: =SUM(D45:D53) | E54: =SUM(E45:E53) | F54: =E54/C54 | G54: =SUM(G45:G53) | H54: =SUM(H45:H53) | I54: =H54/C54

Sheet Client Rate Ranking
A1: Clients ranked by revenue lost to lower rates
A2: Rate level: 100% = pays the best client’s rate on the same route and quarter. Revenue lost = shortfall against that rate.
A4: Rank | B4: Client | C4: Rate level | D4: Verdict | E4: Revenue lost (₦) | F4: Share of total lost | G4: Lost if priced at highest rate (₦) | H4: Trips on compared routes | I4: Revenue on compared routes (₦) | J4: 2026 revenue (₦) | K4: Routes with biggest gaps
A5: 1 | B5: Jamara | C5: 0.88864022 | D5: Below peers | E5: 52915476 | F5: =IF($E$27=0,0,E5/$E$27) | G5: 68525639 | H5: 175 | I5: 3.9392514e+08 | J5: 4.7832228e+08 | K5: Lagos → Abuja, Lagos → Kano, Lagos → Benin
A6: 2 | B6: MEGA MANU | C6: 0.89551265 | D6: Below peers | E6: 23787322 | F6: =IF($E$27=0,0,E6/$E$27) | G6: 41530328 | H6: 121 | I6: 2.4241953e+08 | J6: 2.4630395e+08 | K6: Lagos → Kano, Lagos → Ibadan, Lagos → Abuja
A7: 3 | B7: Lacasera | C7: 0.64565312 | D7: Well below peers | E7: 14209890 | F7: =IF($E$27=0,0,E7/$E$27) | G7: 14209890 | H7: 24 | I7: 28381995 | J7: 51736810 | K7: Lagos → Benin
A8: 4 | B8: JUBAILI AGROTEC | C8: 0.74606206 | D8: Well below peers | E8: 5694126.3 | F8: =IF($E$27=0,0,E8/$E$27) | G8: 6177712.4 | H8: 8 | I8: 13593464 | J8: 1.1060117e+08 | K8: Ibadan → Abuja, Ibadan → Ekpoma, Ibadan → Kaduna
A9: 5 | B9: VENDARA | C9: 0.93560814 | D9: Below peers | E9: 5627459.2 | F9: =IF($E$27=0,0,E9/$E$27) | G9: 6107459.2 | H9: 24 | I9: 88279070 | J9: 88279070 | K9: Lagos → Kano, Lagos → Onitsha
A10: 6 | B10: NIGER BISCUITS | C10: 0.91364002 | D10: Below peers | E10: 2599292 | F10: =IF($E$27=0,0,E10/$E$27) | G10: 4250000 | H10: 11 | I10: 26112791 | J10: 43323256 | K10: Lagos → Owerri, Lagos → Abuja, Lagos → PHC
A11: 7 | B11: NATURAL BEAUTY | C11: 0.98267631 | D11: Close to top | E11: 2506976.7 | F11: =IF($E$27=0,0,E11/$E$27) | G11: 16911628 | H11: 33 | I11: 1.2599767e+08 | J11: 1.2646279e+08 | K11: Lagos → Kano
A12: 8 | B12: KD & SONS | C12: 0.50900997 | D12: Well below peers | E12: 2007569.7 | F12: =IF($E$27=0,0,E12/$E$27) | G12: 2007569.7 | H12: 2 | I12: 2081250 | J12: 2081250 | K12: Kaduna (Kudenda) → Ibadan
A13: 9 | B13: GIVANAS | C13: 0.97345383 | D13: Close to top | E13: 1373058 | F13: =IF($E$27=0,0,E13/$E$27) | G13: 4396778.9 | H13: 23 | I13: 43741860 | J13: 43741860 | K13: Lagos → Onitsha
A14: 10 | B14: INTERSTYLE | C14: 0.93593162 | D14: Below peers | E14: 1227907 | F14: =IF($E$27=0,0,E14/$E$27) | G14: 1227907 | H14: 6 | I14: 17841860 | J14: 25655814 | K14: Lagos → Abuja, Lagos → PHC
A15: 11 | B15: B2B-ORCA DECO LIMITED(MR OTEGA) | C15: 0.67342174 | D15: Well below peers | E15: 1115393.2 | F15: =IF($E$27=0,0,E15/$E$27) | G15: 1115393.2 | H15: 1 | I15: 2300000 | J15: 2300000 | K15: Lagos → Asaba
A16: 12 | B16: NBL | C16: 0.93304459 | D16: Below peers | E16: 1058582.5 | F16: =IF($E$27=0,0,E16/$E$27) | G16: 5488758.1 | H16: 25 | I16: 44470130 | J16: 5.766846e+08 | K16: Lagos → Ibadan, Lagos → Ijebu Ode
... A26: 22 | B26: ORCA DECO LIMITED | C26: 1 | D26: At top rate | E26: 0 | F26: =IF($E$27=0,0,E26/$E$27) | G26: 0 | H26: 5 | I26: 14374086 | J26: 1.2501978e+08 | K26: —
B27: Total | E27: =SUM(E5:E26) | G27: =SUM(G5:G26) | H27: =SUM(H5:H26) | I27: =SUM(I5:I26) | J27: =SUM(J5:J26)

Sheet Rate Gaps by Route
A1: Where each client pays less than the best-paying client
A3: Quarter | B3: Route | C3: Vehicle | D3: Client (lower rate) | E3: Trips | F3: Their avg rate (₦) | G3: Best-paying client | H3: Best client trips | I3: Best avg rate (₦) | J3: Rate level | K3: Revenue lost (₦) | L3: Highest rate on route (₦) | M3: Lost if at highest (₦)
A4: Q1 | B4: Lagos → Benin | C4: Haulage | D4: Lacasera | E4: 18 | F4: 881463.21 | G4: NBL | H4: 2 | I4: 1670901.5 | J4: =F4/I4 | K4: =MAX(0,I4-F4)*E4 | L4: 1670901.5 | M4: 14209890
A5: Q3 | B5: Lagos → Abuja | C5: Haulage | D5: Jamara | E5: 22 | F5: 2692727.3 | G5: INTERSTYLE | H5: 3 | I5: 3162790.7 | J5: =F5/I5 | K5: =MAX(0,I5-F5)*E5 | L5: 3162790.7 | M5: 10341395
A6: Q2 | B6: Lagos → Abuja | C6: Haulage | D6: Jamara | E6: 12 | F6: 2794554.2 | G6: ORCA DECO LIMITED | H6: 1 | I6: 3627907 | J6: =F6/I6 | K6: =MAX(0,I6-F6)*E6 | L6: 3627907 | M6: 10000234
A7: Q3 | B7: Lagos → Kano | C7: Haulage | D7: Jamara | E7: 16 | F7: 3775000 | G7: SASO | H7: 10 | I7: 4400000 | J7: =F7/I7 | K7: =MAX(0,I7-F7)*E7 | L7: 4400000 | M7: 10000000
A8: Q3 | B8: Lagos → Kano | C8: Haulage | D8: MEGA MANU | E8: 11 | F8: 3771670.2 | G8: SASO | H8: 10 | I8: 4400000 | J8: =F8/I8 | K8: =MAX(0,I8-F8)*E8 | L8: 4400000 | M8: 6911627.9
A9: Q1 | B9: Lagos → PHC | C9: Haulage | D9: Jamara | E9: 17 | F9: 2035294.1 | G9: GIVANAS | H9: 1 | I9: 2325581.4 | J9: =F9/I9 | K9: =MAX(0,I9-F9)*E9 | L9: 2325581.4 | M9: 4934883.7
A10: Q2 | B10: Lagos → Kano | C10: Haulage | D10: Jamara | E10: 10 | F10: 3864820 | G10: SASO | H10: 8 | I10: 4340000 | J10: =F10/I10 | K10: =MAX(0,I10-F10)*E10 | L10: 4400000 | M10: 5351800
A11: Q1 | B11: Lagos → Benin | C11: Haulage | D11: Jamara | E11: 7 | F11: 1003543.3 | G11: NBL | H11: 2 | I11: 1670901.5 | J11: =F11/I11 | K11: =MAX(0,I11-F11)*E11 | L11: 1670901.5 | M11: 4671507.4
A12: Q2 | B12: Lagos → Ibadan | C12: Haulage | D12: MEGA MANU | E12: 28 | F12: 636943.52 | G12: MAMUDA BEVERAGES CO. LTD | H12: 5 | I12: 790697.67 | J12: =F12/I12 | K12: =MAX(0,I12-F12)*E12 | L12: 800000 | M12: 4565581.4
A13: Q2 | B13: Lagos → Kano | C13: Haulage | D13: MEGA MANU | E13: 13 | F13: 4089445.4 | G13: SASO | H13: 8 | I13: 4340000 | J13: =F13/I13 | K13: =MAX(0,I13-F13)*E13 | L13: 4400000 | M13: 4037209.3
A14: Q1 | B14: Lagos → Kano | C14: Haulage | D14: MEGA MANU | E14: 14 | F14: 3162790.7 | G14: NATURAL BEAUTY | H14: 14 | I14: 3386046.5 | J14: =F14/I14 | K14: =MAX(0,I14-F14)*E14 | L14: 4372093 | M14: 16930233
A15: Q3 | B15: Lagos → Kano | C15: Haulage | D15: VENDARA | E15: 11 | F15: 4139534.9 | G15: SASO | H15: 10 | I15: 4400000 | J15: =F15/I15 | K15: =MAX(0,I15-F15)*E15 | L15: 4400000 | M15: 2865116.3
... A65: Q1 | B65: Ibadan → Oyo | C65: Haulage | D65: JUBAILI AGROTEC | E65: 1 | F65: 279069.77 | G65: NBL | H65: 1 | I65: 283860 | J65: =F65/I65 | K65: =MAX(0,I65-F65)*E65 | L65: 283860 | M65: 4790.2326
D66: Total | K66: =SUM(K4:K65) | M66: =SUM(M4:M65)

Sheet Turnaround Table
A1: Turnaround time — one leg (drop point → loading bay)
A2: Your table. Edit any Days value (yellow) and the truck requirement recalculates. Add new routes at the bottom; the Key fills itself.
A4: From (drop point) | B4: To (loading bay) | C4: Days (one leg) | D4: Key
A5: Abuja | B5: APAPA | C5: 2 | D5: =UPPER(A5)&">"&UPPER(B5)
A6: Warri | B6: APAPA | C6: 1 | D6: =UPPER(A6)&">"&UPPER(B6)
A7: Abuja | B7: Abuja | C7: 1 | D7: =UPPER(A7)&">"&UPPER(B7)
A8: ABAJI | B8: IBADAN | C8: 2 | D8: =UPPER(A8)&">"&UPPER(B8)
A9: AYANGBA | B9: IBADAN | C9: 2 | D9: =UPPER(A9)&">"&UPPER(B9)
A10: Aba | B10: IBADAN | C10: 2 | D10: =UPPER(A10)&">"&UPPER(B10)
A11: Abakalike | B11: IBADAN | C11: 2 | D11: =UPPER(A11)&">"&UPPER(B11)
A12: Abuja | B12: IBADAN | C12: 2 | D12: =UPPER(A12)&">"&UPPER(B12)
A13: Agbor | B13: IBADAN | C13: 1 | D13: =UPPER(A13)&">"&UPPER(B13)
A14: Bauchi | B14: IBADAN | C14: 3 | D14: =UPPER(A14)&">"&UPPER(B14)
A15: Bida | B15: IBADAN | C15: 1 | D15: =UPPER(A15)&">"&UPPER(B15)
A16: Ekpoma | B16: IBADAN | C16: 1 | D16: =UPPER(A16)&">"&UPPER(B16)
... A201: Port Harcourt | B201: Benin | C201: 2 | D201: =UPPER(A201)&">"&UPPER(B201)
D202: =IF(A202="","",UPPER(A202)&">"&UPPER(B202))
D203: =IF(A203="","",UPPER(A203)&">"&UPPER(B203))
D204: =IF(A204="","",UPPER(A204)&">"&UPPER(B204))
D205: =IF(A205="","",UPPER(A205)&">"&UPPER(B205))
D206: =IF(A206="","",UPPER(A206)&">"&UPPER(B206))
D207: =IF(A207="","",UPPER(A207)&">"&UPPER(B207))
D208: =IF(A208="","",UPPER(A208)&">"&UPPER(B208))
D209: =IF(A209="","",UPPER(A209)&">"&UPPER(B209))
D210: =IF(A210="","",UPPER(A210)&">"&UPPER(B210))
D211: =IF(A211="","",UPPER(A211)&">"&UPPER(B211))
D212: =IF(A212="","",UPPER(A212)&">"&UPPER(B212))
D213: =IF(A213="","",UPPER(A213)&">"&UPPER(B213))
... D231: =IF(A231="","",UPPER(A231)&">"&UPPER(B231))

Sheet Truck Requirement
A1: Truck requirement per client — monthly rotation
A2: A truck rotates on its route through the month. Trips one truck can do per month = whole number of (operating days ÷ round-trip days). Example: 6-day round trip → 4 trips per truck per month (one a week), so 4 trips a month need 1 truck. Trucks needed = trips in the month ÷ trips per truck, added up across the client's routes and rounded up per client.
A4: Operating days per truck per month | B4: 26 | C4: Days a truck is available to run (26 allows for Sundays and maintenance; use 30 for every day).
A5: Default one-leg days for routes not in your table | B5: 2 | C5: Used only where a route has no match and no override (red rows on the route sheet).
A7: Trips one truck can do in a month:
A8: 2-day round trip (Lagos/Ibadan local) | B8: =MAX(1,INT('Truck Requirement'!$B$4/2)) | C8: trip(s) per truck per month
A9: 4-day round trip (e.g. PHC, Onitsha, Benin from Ibadan) | B9: =MAX(1,INT('Truck Requirement'!$B$4/4)) | C9: trip(s) per truck per month
A10: 6-day round trip (e.g. Abuja, Kaduna) | B10: =MAX(1,INT('Truck Requirement'!$B$4/6)) | C10: trip(s) per truck per month
A11: 8-day round trip (e.g. Kano from Lagos) | B11: =MAX(1,INT('Truck Requirement'!$B$4/8)) | C11: trip(s) per truck per month
A12: 10-day round trip (e.g. Yola, Maiduguri) | B12: =MAX(1,INT('Truck Requirement'!$B$4/10)) | C12: trip(s) per truck per month
B14: Trucks needed each month (trucks rotating on their routes)
A15: Client | B15: Jan | C15: Feb | D15: Mar | E15: Apr | F15: May | G15: Jun | H15: Jul | I15: Aug | J15: Sep | K15: Months with trips | L15: Avg trips per month | M15: Typical month (avg trucks) | N15: Peak month (trucks) | O15: Peak month Jul–Sep | P15: Avg round-trip days
A16: NBL | B16: =ROUNDUP(SUMIFS('Truck Req by Route'!$V$5:$V$320,'Truck Req by Route'!$A$5:$A$320,$A16),0) | C16: =ROUNDUP(SUMIFS('Truck Req by Route'!$W$5:$W$320,'Truck Req by Route'!$A$5:$A$320,$A16),0) | D16: =ROUNDUP(SUMIFS('Truck Req by Route'!$X$5:$X$320,'Truck Req by Route'!$A$5:$A$320,$A16),0) | E16: =ROUNDUP(SUMIFS('Truck Req by Route'!$Y$5:$Y$320,'Truck Req by Route'!$A$5:$A$320,$A16),0) | F16: =ROUNDUP(SUMIFS('Truck Req by Route'!$Z$5:$Z$320,'Truck Req by Route'!$A$5:$A$320,$A16),0) | G16: =ROUNDUP(SUMIFS('Truck Req by Route'!$AA$5:$AA$320,'Truck Req by Route'!$A$5:$A$320,$A16),0) | H16: =ROUNDUP(SUMIFS('Truck Req by Route'!$AB$5:$AB$320,'Truck Req by Route'!$A$5:$A$320,$A16),0) | I16: =ROUNDUP(SUMIFS('Truck Req by Route'!$AC$5:$AC$320,'Truck Req by Route'!$A$5:$A$320,$A16),0) | J16: =ROUNDUP(SUMIFS('Truck Req by Route'!$AD$5:$AD$320,'Truck Req by Route'!$A$5:$A$320,$A16),0) | K16: =COUNTIF(B16:J16,">0") | L16: =IF(K16=0,0,SUMIFS('Truck Req by Route'!$L$5:$L$320,'Truck Req by Route'!$A$5:$A$320,$A16)/K16) | M16: =IFERROR(AVERAGEIF(B16:J16,">0"),0) | N16: =MAX(B16:J16) | O16: =MAX(H16:J16) | P16: =IFERROR(SUMPRODUCT(('Truck Req by Route'!$A$5:$A$320=$A16)*'Truck Req by Route'!$L$5:$L$320*'Truck Req by Route'!$J$5:$J$320)/SUMIFS('Truck Req by Route'!$L$5:$L$320,'Truck Req by Route'!$A$5:$A$320,$A16),"")
A17: ORCA DECO LIMITED | B17: =ROUNDUP(SUMIFS('Truck Req by Route'!$V$5:$V$320,'Truck Req by Route'!$A$5:$A$320,$A17),0) | C17: =ROUNDUP(SUMIFS('Truck Req by Route'!$W$5:$W$320,'Truck Req by Route'!$A$5:$A$320,$A17),0) | D17: =ROUNDUP(SUMIFS('Truck Req by Route'!$X$5:$X$320,'Truck Req by Route'!$A$5:$A$320,$A17),0) | E17: =ROUNDUP(SUMIFS('Truck Req by Route'!$Y$5:$Y$320,'Truck Req by Route'!$A$5:$A$320,$A17),0) | F17: =ROUNDUP(SUMIFS('Truck Req by Route'!$Z$5:$Z$320,'Truck Req by Route'!$A$5:$A$320,$A17),0) | G17: =ROUNDUP(SUMIFS('Truck Req by Route'!$AA$5:$AA$320,'Truck Req by Route'!$A$5:$A$320,$A17),0) | H17: =ROUNDUP(SUMIFS('Truck Req by Route'!$AB$5:$AB$320,'Truck Req by Route'!$A$5:$A$320,$A17),0) | I17: =ROUNDUP(SUMIFS('Truck Req by Route'!$AC$5:$AC$320,'Truck Req by Route'!$A$5:$A$320,$A17),0) | J17: =ROUNDUP(SUMIFS('Truck Req by Route'!$AD$5:$AD$320,'Truck Req by Route'!$A$5:$A$320,$A17),0) | K17: =COUNTIF(B17:J17,">0") | L17: =IF(K17=0,0,SUMIFS('Truck Req by Route'!$L$5:$L$320,'Truck Req by Route'!$A$5:$A$320,$A17)/K17) | M17: =IFERROR(AVERAGEIF(B17:J17,">0"),0) | N17: =MAX(B17:J17) | O17: =MAX(H17:J17) | P17: =IFERROR(SUMPRODUCT(('Truck Req by Route'!$A$5:$A$320=$A17)*'Truck Req by Route'!$L$5:$L$320*'Truck Req by Route'!$J$5:$J$320)/SUMIFS('Truck Req by Route'!$L$5:$L$320,'Truck Req by Route'!$A$5:$A$320,$A17),"")
A18: Jamara | B18: =ROUNDUP(SUMIFS('Truck Req by Route'!$V$5:$V$320,'Truck Req by Route'!$A$5:$A$320,$A18),0) | C18: =ROUNDUP(SUMIFS('Truck Req by Route'!$W$5:$W$320,'Truck Req by Route'!$A$5:$A$320,$A18),0) | D18: =ROUNDUP(SUMIFS('Truck Req by Route'!$X$5:$X$320,'Truck Req by Route'!$A$5:$A$320,$A18),0) | E18: =ROUNDUP(SUMIFS('Truck Req by Route'!$Y$5:$Y$320,'Truck Req by Route'!$A$5:$A$320,$A18),0) | F18: =ROUNDUP(SUMIFS('Truck Req by Route'!$Z$5:$Z$320,'Truck Req by Route'!$A$5:$A$320,$A18),0) | G18: =ROUNDUP(SUMIFS('Truck Req by Route'!$AA$5:$AA$320,'Truck Req by Route'!$A$5:$A$320,$A18),0) | H18: =ROUNDUP(SUMIFS('Truck Req by Route'!$AB$5:$AB$320,'Truck Req by Route'!$A$5:$A$320,$A18),0) | I18: =ROUNDUP(SUMIFS('Truck Req by Route'!$AC$5:$AC$320,'Truck Req by Route'!$A$5:$A$320,$A18),0) | J18: =ROUNDUP(SUMIFS('Truck Req by Route'!$AD$5:$AD$320,'Truck Req by Route'!$A$5:$A$320,$A18),0) | K18: =COUNTIF(B18:J18,">0") | L18: =IF(K18=0,0,SUMIFS('Truck Req by Route'!$L$5:$L$320,'Truck Req by Route'!$A$5:$A$320,$A18)/K18) | M18: =IFERROR(AVERAGEIF(B18:J18,">0"),0) | N18: =MAX(B18:J18) | O18: =MAX(H18:J18) | P18: =IFERROR(SUMPRODUCT(('Truck Req by Route'!$A$5:$A$320=$A18)*'Truck Req by Route'!$L$5:$L$320*'Truck Req by Route'!$J$5:$J$320)/SUMIFS('Truck Req by Route'!$L$5:$L$320,'Truck Req by Route'!$A$5:$A$320,$A18),"")
A19: MEGA MANU | B19: =ROUNDUP(SUMIFS('Truck Req by Route'!$V$5:$V$320,'Truck Req by Route'!$A$5:$A$320,$A19),0) | C19: =ROUNDUP(SUMIFS('Truck Req by Route'!$W$5:$W$320,'Truck Req by Route'!$A$5:$A$320,$A19),0) | D19: =ROUNDUP(SUMIFS('Truck Req by Route'!$X$5:$X$320,'Truck Req by Route'!$A$5:$A$320,$A19),0) | E19: =ROUNDUP(SUMIFS('Truck Req by Route'!$Y$5:$Y$320,'Truck Req by Route'!$A$5:$A$320,$A19),0) | F19: =ROUNDUP(SUMIFS('Truck Req by Route'!$Z$5:$Z$320,'Truck Req by Route'!$A$5:$A$320,$A19),0) | G19: =ROUNDUP(SUMIFS('Truck Req by Route'!$AA$5:$AA$320,'Truck Req by Route'!$A$5:$A$320,$A19),0) | H19: =ROUNDUP(SUMIFS('Truck Req by Route'!$AB$5:$AB$320,'Truck Req by Route'!$A$5:$A$320,$A19),0) | I19: =ROUNDUP(SUMIFS('Truck Req by Route'!$AC$5:$AC$320,'Truck Req by Route'!$A$5:$A$320,$A19),0) | J19: =ROUNDUP(SUMIFS('Truck Req by Route'!$AD$5:$AD$320,'Truck Req by Route'!$A$5:$A$320,$A19),0) | K19: =COUNTIF(B19:J19,">0") | L19: =IF(K19=0,0,SUMIFS('Truck Req by Route'!$L$5:$L$320,'Truck Req by Route'!$A$5:$A$320,$A19)/K19) | M19: =IFERROR(AVERAGEIF(B19:J19,">0"),0) | N19: =MAX(B19:J19) | O19: =MAX(H19:J19) | P19: =IFERROR(SUMPRODUCT(('Truck Req by Route'!$A$5:$A$320=$A19)*'Truck Req by Route'!$L$5:$L$320*'Truck Req by Route'!$J$5:$J$320)/SUMIFS('Truck Req by Route'!$L$5:$L$320,'Truck Req by Route'!$A$5:$A$320,$A19),"")
A20: Lacasera | B20: =ROUNDUP(SUMIFS('Truck Req by Route'!$V$5:$V$320,'Truck Req by Route'!$A$5:$A$320,$A20),0) | C20: =ROUNDUP(SUMIFS('Truck Req by Route'!$W$5:$W$320,'Truck Req by Route'!$A$5:$A$320,$A20),0) | D20: =ROUNDUP(SUMIFS('Truck Req by Route'!$X$5:$X$320,'Truck Req by Route'!$A$5:$A$320,$A20),0) | E20: =ROUNDUP(SUMIFS('Truck Req by Route'!$Y$5:$Y$320,'Truck Req by Route'!$A$5:$A$320,$A20),0) | F20: =ROUNDUP(SUMIFS('Truck Req by Route'!$Z$5:$Z$320,'Truck Req by Route'!$A$5:$A$320,$A20),0) | G20: =ROUNDUP(SUMIFS('Truck Req by Route'!$AA$5:$AA$320,'Truck Req by Route'!$A$5:$A$320,$A20),0) | H20: =ROUNDUP(SUMIFS('Truck Req by Route'!$AB$5:$AB$320,'Truck Req by Route'!$A$5:$A$320,$A20),0) | I20: =ROUNDUP(SUMIFS('Truck Req by Route'!$AC$5:$AC$320,'Truck Req by Route'!$A$5:$A$320,$A20),0) | J20: =ROUNDUP(SUMIFS('Truck Req by Route'!$AD$5:$AD$320,'Truck Req by Route'!$A$5:$A$320,$A20),0) | K20: =COUNTIF(B20:J20,">0") | L20: =IF(K20=0,0,SUMIFS('Truck Req by Route'!$L$5:$L$320,'Truck Req by Route'!$A$5:$A$320,$A20)/K20) | M20: =IFERROR(AVERAGEIF(B20:J20,">0"),0) | N20: =MAX(B20:J20) | O20: =MAX(H20:J20) | P20: =IFERROR(SUMPRODUCT(('Truck Req by Route'!$A$5:$A$320=$A20)*'Truck Req by Route'!$L$5:$L$320*'Truck Req by Route'!$J$5:$J$320)/SUMIFS('Truck Req by Route'!$L$5:$L$320,'Truck Req by Route'!$A$5:$A$320,$A20),"")
A21: AB-INBEV | B21: =ROUNDUP(SUMIFS('Truck Req by Route'!$V$5:$V$320,'Truck Req by Route'!$A$5:$A$320,$A21),0) | C21: =ROUNDUP(SUMIFS('Truck Req by Route'!$W$5:$W$320,'Truck Req by Route'!$A$5:$A$320,$A21),0) | D21: =ROUNDUP(SUMIFS('Truck Req by Route'!$X$5:$X$320,'Truck Req by Route'!$A$5:$A$320,$A21),0) | E21: =ROUNDUP(SUMIFS('Truck Req by Route'!$Y$5:$Y$320,'Truck Req by Route'!$A$5:$A$320,$A21),0) | F21: =ROUNDUP(SUMIFS('Truck Req by Route'!$Z$5:$Z$320,'Truck Req by Route'!$A$5:$A$320,$A21),0) | G21: =ROUNDUP(SUMIFS('Truck Req by Route'!$AA$5:$AA$320,'Truck Req by Route'!$A$5:$A$320,$A21),0) | H21: =ROUNDUP(SUMIFS('Truck Req by Route'!$AB$5:$AB$320,'Truck Req by Route'!$A$5:$A$320,$A21),0) | I21: =ROUNDUP(SUMIFS('Truck Req by Route'!$AC$5:$AC$320,'Truck Req by Route'!$A$5:$A$320,$A21),0) | J21: =ROUNDUP(SUMIFS('Truck Req by Route'!$AD$5:$AD$320,'Truck Req by Route'!$A$5:$A$320,$A21),0) | K21: =COUNTIF(B21:J21,">0") | L21: =IF(K21=0,0,SUMIFS('Truck Req by Route'!$L$5:$L$320,'Truck Req by Route'!$A$5:$A$320,$A21)/K21) | M21: =IFERROR(AVERAGEIF(B21:J21,">0"),0) | N21: =MAX(B21:J21) | O21: =MAX(H21:J21) | P21: =IFERROR(SUMPRODUCT(('Truck Req by Route'!$A$5:$A$320=$A21)*'Truck Req by Route'!$L$5:$L$320*'Truck Req by Route'!$J$5:$J$320)/SUMIFS('Truck Req by Route'!$L$5:$L$320,'Truck Req by Route'!$A$5:$A$320,$A21),"")
A22: JUBAILI AGROTEC | B22: =ROUNDUP(SUMIFS('Truck Req by Route'!$V$5:$V$320,'Truck Req by Route'!$A$5:$A$320,$A22),0) | C22: =ROUNDUP(SUMIFS('Truck Req by Route'!$W$5:$W$320,'Truck Req by Route'!$A$5:$A$320,$A22),0) | D22: =ROUNDUP(SUMIFS('Truck Req by Route'!$X$5:$X$320,'Truck Req by Route'!$A$5:$A$320,$A22),0) | E22: =ROUNDUP(SUMIFS('Truck Req by Route'!$Y$5:$Y$320,'Truck Req by Route'!$A$5:$A$320,$A22),0) | F22: =ROUNDUP(SUMIFS('Truck Req by Route'!$Z$5:$Z$320,'Truck Req by Route'!$A$5:$A$320,$A22),0) | G22: =ROUNDUP(SUMIFS('Truck Req by Route'!$AA$5:$AA$320,'Truck Req by Route'!$A$5:$A$320,$A22),0) | H22: =ROUNDUP(SUMIFS('Truck Req by Route'!$AB$5:$AB$320,'Truck Req by Route'!$A$5:$A$320,$A22),0) | I22: =ROUNDUP(SUMIFS('Truck Req by Route'!$AC$5:$AC$320,'Truck Req by Route'!$A$5:$A$320,$A22),0) | J22: =ROUNDUP(SUMIFS('Truck Req by Route'!$AD$5:$AD$320,'Truck Req by Route'!$A$5:$A$320,$A22),0) | K22: =COUNTIF(B22:J22,">0") | L22: =IF(K22=0,0,SUMIFS('Truck Req by Route'!$L$5:$L$320,'Truck Req by Route'!$A$5:$A$320,$A22)/K22) | M22: =IFERROR(AVERAGEIF(B22:J22,">0"),0) | N22: =MAX(B22:J22) | O22: =MAX(H22:J22) | P22: =IFERROR(SUMPRODUCT(('Truck Req by Route'!$A$5:$A$320=$A22)*'Truck Req by Route'!$L$5:$L$320*'Truck Req by Route'!$J$5:$J$320)/SUMIFS('Truck Req by Route'!$L$5:$L$320,'Truck Req by Route'!$A$5:$A$320,$A22),"")
A23: SASO | B23: =ROUNDUP(SUMIFS('Truck Req by Route'!$V$5:$V$320,'Truck Req by Route'!$A$5:$A$320,$A23),0) | C23: =ROUNDUP(SUMIFS('Truck Req by Route'!$W$5:$W$320,'Truck Req by Route'!$A$5:$A$320,$A23),0) | D23: =ROUNDUP(SUMIFS('Truck Req by Route'!$X$5:$X$320,'Truck Req by Route'!$A$5:$A$320,$A23),0) | E23: =ROUNDUP(SUMIFS('Truck Req by Route'!$Y$5:$Y$320,'Truck Req by Route'!$A$5:$A$320,$A23),0) | F23: =ROUNDUP(SUMIFS('Truck Req by Route'!$Z$5:$Z$320,'Truck Req by Route'!$A$5:$A$320,$A23),0) | G23: =ROUNDUP(SUMIFS('Truck Req by Route'!$AA$5:$AA$320,'Truck Req by Route'!$A$5:$A$320,$A23),0) | H23: =ROUNDUP(SUMIFS('Truck Req by Route'!$AB$5:$AB$320,'Truck Req by Route'!$A$5:$A$320,$A23),0) | I23: =ROUNDUP(SUMIFS('Truck Req by Route'!$AC$5:$AC$320,'Truck Req by Route'!$A$5:$A$320,$A23),0) | J23: =ROUNDUP(SUMIFS('Truck Req by Route'!$AD$5:$AD$320,'Truck Req by Route'!$A$5:$A$320,$A23),0) | K23: =COUNTIF(B23:J23,">0") | L23: =IF(K23=0,0,SUMIFS('Truck Req by Route'!$L$5:$L$320,'Truck Req by Route'!$A$5:$A$320,$A23)/K23) | M23: =IFERROR(AVERAGEIF(B23:J23,">0"),0) | N23: =MAX(B23:J23) | O23: =MAX(H23:J23) | P23: =IFERROR(SUMPRODUCT(('Truck Req by Route'!$A$5:$A$320=$A23)*'Truck Req by Route'!$L$5:$L$320*'Truck Req by Route'!$J$5:$J$320)/SUMIFS('Truck Req by Route'!$L$5:$L$320,'Truck Req by Route'!$A$5:$A$320,$A23),"")
A24: NATURAL BEAUTY | B24: =ROUNDUP(SUMIFS('Truck Req by Route'!$V$5:$V$320,'Truck Req by Route'!$A$5:$A$320,$A24),0) | C24: =ROUNDUP(SUMIFS('Truck Req by Route'!$W$5:$W$320,'Truck Req by Route'!$A$5:$A$320,$A24),0) | D24: =ROUNDUP(SUMIFS('Truck Req by Route'!$X$5:$X$320,'Truck Req by Route'!$A$5:$A$320,$A24),0) | E24: =ROUNDUP(SUMIFS('Truck Req by Route'!$Y$5:$Y$320,'Truck Req by Route'!$A$5:$A$320,$A24),0) | F24: =ROUNDUP(SUMIFS('Truck Req by Route'!$Z$5:$Z$320,'Truck Req by Route'!$A$5:$A$320,$A24),0) | G24: =ROUNDUP(SUMIFS('Truck Req by Route'!$AA$5:$AA$320,'Truck Req by Route'!$A$5:$A$320,$A24),0) | H24: =ROUNDUP(SUMIFS('Truck Req by Route'!$AB$5:$AB$320,'Truck Req by Route'!$A$5:$A$320,$A24),0) | I24: =ROUNDUP(SUMIFS('Truck Req by Route'!$AC$5:$AC$320,'Truck Req by Route'!$A$5:$A$320,$A24),0) | J24: =ROUNDUP(SUMIFS('Truck Req by Route'!$AD$5:$AD$320,'Truck Req by Route'!$A$5:$A$320,$A24),0) | K24: =COUNTIF(B24:J24,">0") | L24: =IF(K24=0,0,SUMIFS('Truck Req by Route'!$L$5:$L$320,'Truck Req by Route'!$A$5:$A$320,$A24)/K24) | M24: =IFERROR(AVERAGEIF(B24:J24,">0"),0) | N24: =MAX(B24:J24) | O24: =MAX(H24:J24) | P24: =IFERROR(SUMPRODUCT(('Truck Req by Route'!$A$5:$A$320=$A24)*'Truck Req by Route'!$L$5:$L$320*'Truck Req by Route'!$J$5:$J$320)/SUMIFS('Truck Req by Route'!$L$5:$L$320,'Truck Req by Route'!$A$5:$A$320,$A24),"")
A25: ABBA ABASS | B25: =ROUNDUP(SUMIFS('Truck Req by Route'!$V$5:$V$320,'Truck Req by Route'!$A$5:$A$320,$A25),0) | C25: =ROUNDUP(SUMIFS('Truck Req by Route'!$W$5:$W$320,'Truck Req by Route'!$A$5:$A$320,$A25),0) | D25: =ROUNDUP(SUMIFS('Truck Req by Route'!$X$5:$X$320,'Truck Req by Route'!$A$5:$A$320,$A25),0) | E25: =ROUNDUP(SUMIFS('Truck Req by Route'!$Y$5:$Y$320,'Truck Req by Route'!$A$5:$A$320,$A25),0) | F25: =ROUNDUP(SUMIFS('Truck Req by Route'!$Z$5:$Z$320,'Truck Req by Route'!$A$5:$A$320,$A25),0) | G25: =ROUNDUP(SUMIFS('Truck Req by Route'!$AA$5:$AA$320,'Truck Req by Route'!$A$5:$A$320,$A25),0) | H25: =ROUNDUP(SUMIFS('Truck Req by Route'!$AB$5:$AB$320,'Truck Req by Route'!$A$5:$A$320,$A25),0) | I25: =ROUNDUP(SUMIFS('Truck Req by Route'!$AC$5:$AC$320,'Truck Req by Route'!$A$5:$A$320,$A25),0) | J25: =ROUNDUP(SUMIFS('Truck Req by Route'!$AD$5:$AD$320,'Truck Req by Route'!$A$5:$A$320,$A25),0) | K25: =COUNTIF(B25:J25,">0") | L25: =IF(K25=0,0,SUMIFS('Truck Req by Route'!$L$5:$L$320,'Truck Req by Route'!$A$5:$A$320,$A25)/K25) | M25: =IFERROR(AVERAGEIF(B25:J25,">0"),0) | N25: =MAX(B25:J25) | O25: =MAX(H25:J25) | P25: =IFERROR(SUMPRODUCT(('Truck Req by Route'!$A$5:$A$320=$A25)*'Truck Req by Route'!$L$5:$L$320*'Truck Req by Route'!$J$5:$J$320)/SUMIFS('Truck Req by Route'!$L$5:$L$320,'Truck Req by Route'!$A$5:$A$320,$A25),"")
A26: VENDARA | B26: =ROUNDUP(SUMIFS('Truck Req by Route'!$V$5:$V$320,'Truck Req by Route'!$A$5:$A$320,$A26),0) | C26: =ROUNDUP(SUMIFS('Truck Req by Route'!$W$5:$W$320,'Truck Req by Route'!$A$5:$A$320,$A26),0) | D26: =ROUNDUP(SUMIFS('Truck Req by Route'!$X$5:$X$320,'Truck Req by Route'!$A$5:$A$320,$A26),0) | E26: =ROUNDUP(SUMIFS('Truck Req by Route'!$Y$5:$Y$320,'Truck Req by Route'!$A$5:$A$320,$A26),0) | F26: =ROUNDUP(SUMIFS('Truck Req by Route'!$Z$5:$Z$320,'Truck Req by Route'!$A$5:$A$320,$A26),0) | G26: =ROUNDUP(SUMIFS('Truck Req by Route'!$AA$5:$AA$320,'Truck Req by Route'!$A$5:$A$320,$A26),0) | H26: =ROUNDUP(SUMIFS('Truck Req by Route'!$AB$5:$AB$320,'Truck Req by Route'!$A$5:$A$320,$A26),0) | I26: =ROUNDUP(SUMIFS('Truck Req by Route'!$AC$5:$AC$320,'Truck Req by Route'!$A$5:$A$320,$A26),0) | J26: =ROUNDUP(SUMIFS('Truck Req by Route'!$AD$5:$AD$320,'Truck Req by Route'!$A$5:$A$320,$A26),0) | K26: =COUNTIF(B26:J26,">0") | L26: =IF(K26=0,0,SUMIFS('Truck Req by Route'!$L$5:$L$320,'Truck Req by Route'!$A$5:$A$320,$A26)/K26) | M26: =IFERROR(AVERAGEIF(B26:J26,">0"),0) | N26: =MAX(B26:J26) | O26: =MAX(H26:J26) | P26: =IFERROR(SUMPRODUCT(('Truck Req by Route'!$A$5:$A$320=$A26)*'Truck Req by Route'!$L$5:$L$320*'Truck Req by Route'!$J$5:$J$320)/SUMIFS('Truck Req by Route'!$L$5:$L$320,'Truck Req by Route'!$A$5:$A$320,$A26),"")
A27: GIVANAS | B27: =ROUNDUP(SUMIFS('Truck Req by Route'!$V$5:$V$320,'Truck Req by Route'!$A$5:$A$320,$A27),0) | C27: =ROUNDUP(SUMIFS('Truck Req by Route'!$W$5:$W$320,'Truck Req by Route'!$A$5:$A$320,$A27),0) | D27: =ROUNDUP(SUMIFS('Truck Req by Route'!$X$5:$X$320,'Truck Req by Route'!$A$5:$A$320,$A27),0) | E27: =ROUNDUP(SUMIFS('Truck Req by Route'!$Y$5:$Y$320,'Truck Req by Route'!$A$5:$A$320,$A27),0) | F27: =ROUNDUP(SUMIFS('Truck Req by Route'!$Z$5:$Z$320,'Truck Req by Route'!$A$5:$A$320,$A27),0) | G27: =ROUNDUP(SUMIFS('Truck Req by Route'!$AA$5:$AA$320,'Truck Req by Route'!$A$5:$A$320,$A27),0) | H27: =ROUNDUP(SUMIFS('Truck Req by Route'!$AB$5:$AB$320,'Truck Req by Route'!$A$5:$A$320,$A27),0) | I27: =ROUNDUP(SUMIFS('Truck Req by Route'!$AC$5:$AC$320,'Truck Req by Route'!$A$5:$A$320,$A27),0) | J27: =ROUNDUP(SUMIFS('Truck Req by Route'!$AD$5:$AD$320,'Truck Req by Route'!$A$5:$A$320,$A27),0) | K27: =COUNTIF(B27:J27,">0") | L27: =IF(K27=0,0,SUMIFS('Truck Req by Route'!$L$5:$L$320,'Truck Req by Route'!$A$5:$A$320,$A27)/K27) | M27: =IFERROR(AVERAGEIF(B27:J27,">0"),0) | N27: =MAX(B27:J27) | O27: =MAX(H27:J27) | P27: =IFERROR(SUMPRODUCT(('Truck Req by Route'!$A$5:$A$320=$A27)*'Truck Req by Route'!$L$5:$L$320*'Truck Req by Route'!$J$5:$J$320)/SUMIFS('Truck Req by Route'!$L$5:$L$320,'Truck Req by Route'!$A$5:$A$320,$A27),"")
... A44: SASO-BACKLOAD | B44: =ROUNDUP(SUMIFS('Truck Req by Route'!$V$5:$V$320,'Truck Req by Route'!$A$5:$A$320,$A44),0) | C44: =ROUNDUP(SUMIFS('Truck Req by Route'!$W$5:$W$320,'Truck Req by Route'!$A$5:$A$320,$A44),0) | D44: =ROUNDUP(SUMIFS('Truck Req by Route'!$X$5:$X$320,'Truck Req by Route'!$A$5:$A$320,$A44),0) | E44: =ROUNDUP(SUMIFS('Truck Req by Route'!$Y$5:$Y$320,'Truck Req by Route'!$A$5:$A$320,$A44),0) | F44: =ROUNDUP(SUMIFS('Truck Req by Route'!$Z$5:$Z$320,'Truck Req by Route'!$A$5:$A$320,$A44),0) | G44: =ROUNDUP(SUMIFS('Truck Req by Route'!$AA$5:$AA$320,'Truck Req by Route'!$A$5:$A$320,$A44),0) | H44: =ROUNDUP(SUMIFS('Truck Req by Route'!$AB$5:$AB$320,'Truck Req by Route'!$A$5:$A$320,$A44),0) | I44: =ROUNDUP(SUMIFS('Truck Req by Route'!$AC$5:$AC$320,'Truck Req by Route'!$A$5:$A$320,$A44),0) | J44: =ROUNDUP(SUMIFS('Truck Req by Route'!$AD$5:$AD$320,'Truck Req by Route'!$A$5:$A$320,$A44),0) | K44: =COUNTIF(B44:J44,">0") | L44: =IF(K44=0,0,SUMIFS('Truck Req by Route'!$L$5:$L$320,'Truck Req by Route'!$A$5:$A$320,$A44)/K44) | M44: =IFERROR(AVERAGEIF(B44:J44,">0"),0) | N44: =MAX(B44:J44) | O44: =MAX(H44:J44) | P44: =IFERROR(SUMPRODUCT(('Truck Req by Route'!$A$5:$A$320=$A44)*'Truck Req by Route'!$L$5:$L$320*'Truck Req by Route'!$J$5:$J$320)/SUMIFS('Truck Req by Route'!$L$5:$L$320,'Truck Req by Route'!$A$5:$A$320,$A44),"")
A45: Total — each client has its own trucks (rounded up per client) | B45: =SUM(B16:B44) | C45: =SUM(C16:C44) | D45: =SUM(D16:D44) | E45: =SUM(E16:E44) | F45: =SUM(F16:F44) | G45: =SUM(G16:G44) | H45: =SUM(H16:H44) | I45: =SUM(I16:I44) | J45: =SUM(J16:J44) | M45: =AVERAGE(B45:J45) | N45: =MAX(B45:J45) | O45: =MAX(H45:J45)
A46: Total — trucks shared across clients (smallest fleet) | B46: =ROUNDUP(SUM('Truck Req by Route'!V5:V320),0) | C46: =ROUNDUP(SUM('Truck Req by Route'!W5:W320),0) | D46: =ROUNDUP(SUM('Truck Req by Route'!X5:X320),0) | E46: =ROUNDUP(SUM('Truck Req by Route'!Y5:Y320),0) | F46: =ROUNDUP(SUM('Truck Req by Route'!Z5:Z320),0) | G46: =ROUNDUP(SUM('Truck Req by Route'!AA5:AA320),0) | H46: =ROUNDUP(SUM('Truck Req by Route'!AB5:AB320),0) | I46: =ROUNDUP(SUM('Truck Req by Route'!AC5:AC320),0) | J46: =ROUNDUP(SUM('Truck Req by Route'!AD5:AD320),0) | M46: =AVERAGE(B46:J46) | N46: =MAX(B46:J46) | O46: =MAX(H46:J46)
A49: Own haulage/flat trucks actually used (distinct plate numbers, excl. 3rd party) | B49: 35 | C49: 36 | D49: 37 | E49: 40 | F49: 37 | G49: 37 | H49: 33 | I49: 36 | J49: 35 | M49: =AVERAGE(B49:J49) | N49: =MAX(B49:J49) | O49: =MAX(H49:J49)
A50: Own trucks minus shared-fleet need (positive = spare trucks) | B50: =B49-B46 | C50: =C49-C46 | D50: =D49-D46 | E50: =E49-E46 | F50: =F49-F46 | G50: =G49-G46 | H50: =H49-H46 | I50: =I49-I46 | J50: =J49-J46
A53: Notes
A54: Trips per month come from the 2026 trip log: haulage and flat trucks (treated as one), including 3rd-party trucks. Closed-body/canter and Hiab trips are excluded.
A55: Trucks rotate on their routes through the month: a 6-day round trip gives 4 trips per truck per month (weekly), an 8-day round trip gives 3, a 4-day round trip gives 6.
A56: The second total row shares trucks across clients (a truck that finishes one client’s work takes another’s), so it is the smallest fleet that covers the month on average.
A57: Loading/offloading waits beyond your turnaround days are not included; busy weeks inside a month may need more trucks than the monthly average shows.
A58: Lagos pickup points use the Lagos loading bay, Ibadan depots the Ibadan bay; nearby towns (Ilesa, Akure, Ijebu Ode, Ota, Agbara, Ogere) use the nearest bay; returns toward Lagos/Ibadan use your table in reverse.
A59: 76 trips (5.3%) have no route in your table — mostly NBL depot-to-depot moves (NGB4/NGB5/NGB8, Ama, Kudenda). They use the default days until you add the route or type an override.

Sheet Order Planner
A1: Order planner — trucks needed for a client’s monthly request
A2: Enter the client, pick the route (turnaround key from your table) and the trucks/trips requested per month. Operating days per month comes from the Truck Requirement sheet. Yellow cells are inputs.
A4: Client | B4: Route (turnaround key) | C4: Trips requested per month | D4: One-leg days | E4: Round-trip days | F4: Trips one truck can do per month | G4: Truck use (exact) | H4: Trucks needed for this route | J4: Totals by client
A5: Jamara | B5: ABUJA>LAGOS | C5: 4 | D5: =IF(B5="","",IFERROR(INDEX('Turnaround Table'!$C$5:$C$231,MATCH(B5,'Turnaround Table'!$D$5:$D$231,0)),"not in table")) | E5: =IF(ISNUMBER(D5),2*D5,"") | F5: =IF(ISNUMBER(E5),MAX(1,INT('Truck Requirement'!$B$4/E5)),"") | G5: =IF(AND(ISNUMBER(F5),C5<>""),C5/F5,"") | H5: =IF(ISNUMBER(G5),ROUNDUP(G5,0),"") | J5: Client | K5: Trips per month | L5: Trucks needed (shared across the client’s routes)
A6: Jamara | B6: PORT HARCOURT>LAGOS | C6: 6 | D6: =IF(B6="","",IFERROR(INDEX('Turnaround Table'!$C$5:$C$231,MATCH(B6,'Turnaround Table'!$D$5:$D$231,0)),"not in table")) | E6: =IF(ISNUMBER(D6),2*D6,"") | F6: =IF(ISNUMBER(E6),MAX(1,INT('Truck Requirement'!$B$4/E6)),"") | G6: =IF(AND(ISNUMBER(F6),C6<>""),C6/F6,"") | H6: =IF(ISNUMBER(G6),ROUNDUP(G6,0),"") | J6: Jamara | K6: =IF(J6="","",SUMIF($A$5:$A$34,J6,$C$5:$C$34)) | L6: =IF(J6="","",ROUNDUP(SUMIF($A$5:$A$34,J6,$G$5:$G$34),0))
A7: Jamara | B7: KANO>LAGOS | C7: 4 | D7: =IF(B7="","",IFERROR(INDEX('Turnaround Table'!$C$5:$C$231,MATCH(B7,'Turnaround Table'!$D$5:$D$231,0)),"not in table")) | E7: =IF(ISNUMBER(D7),2*D7,"") | F7: =IF(ISNUMBER(E7),MAX(1,INT('Truck Requirement'!$B$4/E7)),"") | G7: =IF(AND(ISNUMBER(F7),C7<>""),C7/F7,"") | H7: =IF(ISNUMBER(G7),ROUNDUP(G7,0),"") | K7: =IF(J7="","",SUMIF($A$5:$A$34,J7,$C$5:$C$34)) | L7: =IF(J7="","",ROUNDUP(SUMIF($A$5:$A$34,J7,$G$5:$G$34),0))
D8: =IF(B8="","",IFERROR(INDEX('Turnaround Table'!$C$5:$C$231,MATCH(B8,'Turnaround Table'!$D$5:$D$231,0)),"not in table")) | E8: =IF(ISNUMBER(D8),2*D8,"") | F8: =IF(ISNUMBER(E8),MAX(1,INT('Truck Requirement'!$B$4/E8)),"") | G8: =IF(AND(ISNUMBER(F8),C8<>""),C8/F8,"") | H8: =IF(ISNUMBER(G8),ROUNDUP(G8,0),"") | K8: =IF(J8="","",SUMIF($A$5:$A$34,J8,$C$5:$C$34)) | L8: =IF(J8="","",ROUNDUP(SUMIF($A$5:$A$34,J8,$G$5:$G$34),0))
D9: =IF(B9="","",IFERROR(INDEX('Turnaround Table'!$C$5:$C$231,MATCH(B9,'Turnaround Table'!$D$5:$D$231,0)),"not in table")) | E9: =IF(ISNUMBER(D9),2*D9,"") | F9: =IF(ISNUMBER(E9),MAX(1,INT('Truck Requirement'!$B$4/E9)),"") | G9: =IF(AND(ISNUMBER(F9),C9<>""),C9/F9,"") | H9: =IF(ISNUMBER(G9),ROUNDUP(G9,0),"") | K9: =IF(J9="","",SUMIF($A$5:$A$34,J9,$C$5:$C$34)) | L9: =IF(J9="","",ROUNDUP(SUMIF($A$5:$A$34,J9,$G$5:$G$34),0))
D10: =IF(B10="","",IFERROR(INDEX('Turnaround Table'!$C$5:$C$231,MATCH(B10,'Turnaround Table'!$D$5:$D$231,0)),"not in table")) | E10: =IF(ISNUMBER(D10),2*D10,"") | F10: =IF(ISNUMBER(E10),MAX(1,INT('Truck Requirement'!$B$4/E10)),"") | G10: =IF(AND(ISNUMBER(F10),C10<>""),C10/F10,"") | H10: =IF(ISNUMBER(G10),ROUNDUP(G10,0),"") | K10: =IF(J10="","",SUMIF($A$5:$A$34,J10,$C$5:$C$34)) | L10: =IF(J10="","",ROUNDUP(SUMIF($A$5:$A$34,J10,$G$5:$G$34),0))
D11: =IF(B11="","",IFERROR(INDEX('Turnaround Table'!$C$5:$C$231,MATCH(B11,'Turnaround Table'!$D$5:$D$231,0)),"not in table")) | E11: =IF(ISNUMBER(D11),2*D11,"") | F11: =IF(ISNUMBER(E11),MAX(1,INT('Truck Requirement'!$B$4/E11)),"") | G11: =IF(AND(ISNUMBER(F11),C11<>""),C11/F11,"") | H11: =IF(ISNUMBER(G11),ROUNDUP(G11,0),"") | K11: =IF(J11="","",SUMIF($A$5:$A$34,J11,$C$5:$C$34)) | L11: =IF(J11="","",ROUNDUP(SUMIF($A$5:$A$34,J11,$G$5:$G$34),0))
D12: =IF(B12="","",IFERROR(INDEX('Turnaround Table'!$C$5:$C$231,MATCH(B12,'Turnaround Table'!$D$5:$D$231,0)),"not in table")) | E12: =IF(ISNUMBER(D12),2*D12,"") | F12: =IF(ISNUMBER(E12),MAX(1,INT('Truck Requirement'!$B$4/E12)),"") | G12: =IF(AND(ISNUMBER(F12),C12<>""),C12/F12,"") | H12: =IF(ISNUMBER(G12),ROUNDUP(G12,0),"") | K12: =IF(J12="","",SUMIF($A$5:$A$34,J12,$C$5:$C$34)) | L12: =IF(J12="","",ROUNDUP(SUMIF($A$5:$A$34,J12,$G$5:$G$34),0))
D13: =IF(B13="","",IFERROR(INDEX('Turnaround Table'!$C$5:$C$231,MATCH(B13,'Turnaround Table'!$D$5:$D$231,0)),"not in table")) | E13: =IF(ISNUMBER(D13),2*D13,"") | F13: =IF(ISNUMBER(E13),MAX(1,INT('Truck Requirement'!$B$4/E13)),"") | G13: =IF(AND(ISNUMBER(F13),C13<>""),C13/F13,"") | H13: =IF(ISNUMBER(G13),ROUNDUP(G13,0),"") | K13: =IF(J13="","",SUMIF($A$5:$A$34,J13,$C$5:$C$34)) | L13: =IF(J13="","",ROUNDUP(SUMIF($A$5:$A$34,J13,$G$5:$G$34),0))
D14: =IF(B14="","",IFERROR(INDEX('Turnaround Table'!$C$5:$C$231,MATCH(B14,'Turnaround Table'!$D$5:$D$231,0)),"not in table")) | E14: =IF(ISNUMBER(D14),2*D14,"") | F14: =IF(ISNUMBER(E14),MAX(1,INT('Truck Requirement'!$B$4/E14)),"") | G14: =IF(AND(ISNUMBER(F14),C14<>""),C14/F14,"") | H14: =IF(ISNUMBER(G14),ROUNDUP(G14,0),"") | K14: =IF(J14="","",SUMIF($A$5:$A$34,J14,$C$5:$C$34)) | L14: =IF(J14="","",ROUNDUP(SUMIF($A$5:$A$34,J14,$G$5:$G$34),0))
D15: =IF(B15="","",IFERROR(INDEX('Turnaround Table'!$C$5:$C$231,MATCH(B15,'Turnaround Table'!$D$5:$D$231,0)),"not in table")) | E15: =IF(ISNUMBER(D15),2*D15,"") | F15: =IF(ISNUMBER(E15),MAX(1,INT('Truck Requirement'!$B$4/E15)),"") | G15: =IF(AND(ISNUMBER(F15),C15<>""),C15/F15,"") | H15: =IF(ISNUMBER(G15),ROUNDUP(G15,0),"") | K15: =IF(J15="","",SUMIF($A$5:$A$34,J15,$C$5:$C$34)) | L15: =IF(J15="","",ROUNDUP(SUMIF($A$5:$A$34,J15,$G$5:$G$34),0))
D16: =IF(B16="","",IFERROR(INDEX('Turnaround Table'!$C$5:$C$231,MATCH(B16,'Turnaround Table'!$D$5:$D$231,0)),"not in table")) | E16: =IF(ISNUMBER(D16),2*D16,"") | F16: =IF(ISNUMBER(E16),MAX(1,INT('Truck Requirement'!$B$4/E16)),"") | G16: =IF(AND(ISNUMBER(F16),C16<>""),C16/F16,"") | H16: =IF(ISNUMBER(G16),ROUNDUP(G16,0),"") | K16: =IF(J16="","",SUMIF($A$5:$A$34,J16,$C$5:$C$34)) | L16: =IF(J16="","",ROUNDUP(SUMIF($A$5:$A$34,J16,$G$5:$G$34),0))
D17: =IF(B17="","",IFERROR(INDEX('Turnaround Table'!$C$5:$C$231,MATCH(B17,'Turnaround Table'!$D$5:$D$231,0)),"not in table")) | E17: =IF(ISNUMBER(D17),2*D17,"") | F17: =IF(ISNUMBER(E17),MAX(1,INT('Truck Requirement'!$B$4/E17)),"") | G17: =IF(AND(ISNUMBER(F17),C17<>""),C17/F17,"") | H17: =IF(ISNUMBER(G17),ROUNDUP(G17,0),"") | K17: =IF(J17="","",SUMIF($A$5:$A$34,J17,$C$5:$C$34)) | L17: =IF(J17="","",ROUNDUP(SUMIF($A$5:$A$34,J17,$G$5:$G$34),0))
D18: =IF(B18="","",IFERROR(INDEX('Turnaround Table'!$C$5:$C$231,MATCH(B18,'Turnaround Table'!$D$5:$D$231,0)),"not in table")) | E18: =IF(ISNUMBER(D18),2*D18,"") | F18: =IF(ISNUMBER(E18),MAX(1,INT('Truck Requirement'!$B$4/E18)),"") | G18: =IF(AND(ISNUMBER(F18),C18<>""),C18/F18,"") | H18: =IF(ISNUMBER(G18),ROUNDUP(G18,0),"") | K18: =IF(J18="","",SUMIF($A$5:$A$34,J18,$C$5:$C$34)) | L18: =IF(J18="","",ROUNDUP(SUMIF($A$5:$A$34,J18,$G$5:$G$34),0))
D19: =IF(B19="","",IFERROR(INDEX('Turnaround Table'!$C$5:$C$231,MATCH(B19,'Turnaround Table'!$D$5:$D$231,0)),"not in table")) | E19: =IF(ISNUMBER(D19),2*D19,"") | F19: =IF(ISNUMBER(E19),MAX(1,INT('Truck Requirement'!$B$4/E19)),"") | G19: =IF(AND(ISNUMBER(F19),C19<>""),C19/F19,"") | H19: =IF(ISNUMBER(G19),ROUNDUP(G19,0),"") | K19: =IF(J19="","",SUMIF($A$5:$A$34,J19,$C$5:$C$34)) | L19: =IF(J19="","",ROUNDUP(SUMIF($A$5:$A$34,J19,$G$5:$G$34),0))
D20: =IF(B20="","",IFERROR(INDEX('Turnaround Table'!$C$5:$C$231,MATCH(B20,'Turnaround Table'!$D$5:$D$231,0)),"not in table")) | E20: =IF(ISNUMBER(D20),2*D20,"") | F20: =IF(ISNUMBER(E20),MAX(1,INT('Truck Requirement'!$B$4/E20)),"") | G20: =IF(AND(ISNUMBER(F20),C20<>""),C20/F20,"") | H20: =IF(ISNUMBER(G20),ROUNDUP(G20,0),"") | K20: =IF(J20="","",SUMIF($A$5:$A$34,J20,$C$5:$C$34)) | L20: =IF(J20="","",ROUNDUP(SUMIF($A$5:$A$34,J20,$G$5:$G$34),0))
D21: =IF(B21="","",IFERROR(INDEX('Turnaround Table'!$C$5:$C$231,MATCH(B21,'Turnaround Table'!$D$5:$D$231,0)),"not in table")) | E21: =IF(ISNUMBER(D21),2*D21,"") | F21: =IF(ISNUMBER(E21),MAX(1,INT('Truck Requirement'!$B$4/E21)),"") | G21: =IF(AND(ISNUMBER(F21),C21<>""),C21/F21,"") | H21: =IF(ISNUMBER(G21),ROUNDUP(G21,0),"")
D22: =IF(B22="","",IFERROR(INDEX('Turnaround Table'!$C$5:$C$231,MATCH(B22,'Turnaround Table'!$D$5:$D$231,0)),"not in table")) | E22: =IF(ISNUMBER(D22),2*D22,"") | F22: =IF(ISNUMBER(E22),MAX(1,INT('Truck Requirement'!$B$4/E22)),"") | G22: =IF(AND(ISNUMBER(F22),C22<>""),C22/F22,"") | H22: =IF(ISNUMBER(G22),ROUNDUP(G22,0),"")
D23: =IF(B23="","",IFERROR(INDEX('Turnaround Table'!$C$5:$C$231,MATCH(B23,'Turnaround Table'!$D$5:$D$231,0)),"not in table")) | E23: =IF(ISNUMBER(D23),2*D23,"") | F23: =IF(ISNUMBER(E23),MAX(1,INT('Truck Requirement'!$B$4/E23)),"") | G23: =IF(AND(ISNUMBER(F23),C23<>""),C23/F23,"") | H23: =IF(ISNUMBER(G23),ROUNDUP(G23,0),"")
D24: =IF(B24="","",IFERROR(INDEX('Turnaround Table'!$C$5:$C$231,MATCH(B24,'Turnaround Table'!$D$5:$D$231,0)),"not in table")) | E24: =IF(ISNUMBER(D24),2*D24,"") | F24: =IF(ISNUMBER(E24),MAX(1,INT('Truck Requirement'!$B$4/E24)),"") | G24: =IF(AND(ISNUMBER(F24),C24<>""),C24/F24,"") | H24: =IF(ISNUMBER(G24),ROUNDUP(G24,0),"")
D25: =IF(B25="","",IFERROR(INDEX('Turnaround Table'!$C$5:$C$231,MATCH(B25,'Turnaround Table'!$D$5:$D$231,0)),"not in table")) | E25: =IF(ISNUMBER(D25),2*D25,"") | F25: =IF(ISNUMBER(E25),MAX(1,INT('Truck Requirement'!$B$4/E25)),"") | G25: =IF(AND(ISNUMBER(F25),C25<>""),C25/F25,"") | H25: =IF(ISNUMBER(G25),ROUNDUP(G25,0),"")
D26: =IF(B26="","",IFERROR(INDEX('Turnaround Table'!$C$5:$C$231,MATCH(B26,'Turnaround Table'!$D$5:$D$231,0)),"not in table")) | E26: =IF(ISNUMBER(D26),2*D26,"") | F26: =IF(ISNUMBER(E26),MAX(1,INT('Truck Requirement'!$B$4/E26)),"") | G26: =IF(AND(ISNUMBER(F26),C26<>""),C26/F26,"") | H26: =IF(ISNUMBER(G26),ROUNDUP(G26,0),"")
D27: =IF(B27="","",IFERROR(INDEX('Turnaround Table'!$C$5:$C$231,MATCH(B27,'Turnaround Table'!$D$5:$D$231,0)),"not in table")) | E27: =IF(ISNUMBER(D27),2*D27,"") | F27: =IF(ISNUMBER(E27),MAX(1,INT('Truck Requirement'!$B$4/E27)),"") | G27: =IF(AND(ISNUMBER(F27),C27<>""),C27/F27,"") | H27: =IF(ISNUMBER(G27),ROUNDUP(G27,0),"")
D28: =IF(B28="","",IFERROR(INDEX('Turnaround Table'!$C$5:$C$231,MATCH(B28,'Turnaround Table'!$D$5:$D$231,0)),"not in table")) | E28: =IF(ISNUMBER(D28),2*D28,"") | F28: =IF(ISNUMBER(E28),MAX(1,INT('Truck Requirement'!$B$4/E28)),"") | G28: =IF(AND(ISNUMBER(F28),C28<>""),C28/F28,"") | H28: =IF(ISNUMBER(G28),ROUNDUP(G28,0),"")
D29: =IF(B29="","",IFERROR(INDEX('Turnaround Table'!$C$5:$C$231,MATCH(B29,'Turnaround Table'!$D$5:$D$231,0)),"not in table")) | E29: =IF(ISNUMBER(D29),2*D29,"") | F29: =IF(ISNUMBER(E29),MAX(1,INT('Truck Requirement'!$B$4/E29)),"") | G29: =IF(AND(ISNUMBER(F29),C29<>""),C29/F29,"") | H29: =IF(ISNUMBER(G29),ROUNDUP(G29,0),"")
D30: =IF(B30="","",IFERROR(INDEX('Turnaround Table'!$C$5:$C$231,MATCH(B30,'Turnaround Table'!$D$5:$D$231,0)),"not in table")) | E30: =IF(ISNUMBER(D30),2*D30,"") | F30: =IF(ISNUMBER(E30),MAX(1,INT('Truck Requirement'!$B$4/E30)),"") | G30: =IF(AND(ISNUMBER(F30),C30<>""),C30/F30,"") | H30: =IF(ISNUMBER(G30),ROUNDUP(G30,0),"")
D31: =IF(B31="","",IFERROR(INDEX('Turnaround Table'!$C$5:$C$231,MATCH(B31,'Turnaround Table'!$D$5:$D$231,0)),"not in table")) | E31: =IF(ISNUMBER(D31),2*D31,"") | F31: =IF(ISNUMBER(E31),MAX(1,INT('Truck Requirement'!$B$4/E31)),"") | G31: =IF(AND(ISNUMBER(F31),C31<>""),C31/F31,"") | H31: =IF(ISNUMBER(G31),ROUNDUP(G31,0),"")
D32: =IF(B32="","",IFERROR(INDEX('Turnaround Table'!$C$5:$C$231,MATCH(B32,'Turnaround Table'!$D$5:$D$231,0)),"not in table")) | E32: =IF(ISNUMBER(D32),2*D32,"") | F32: =IF(ISNUMBER(E32),MAX(1,INT('Truck Requirement'!$B$4/E32)),"") | G32: =IF(AND(ISNUMBER(F32),C32<>""),C32/F32,"") | H32: =IF(ISNUMBER(G32),ROUNDUP(G32,0),"")
... D34: =IF(B34="","",IFERROR(INDEX('Turnaround Table'!$C$5:$C$231,MATCH(B34,'Turnaround Table'!$D$5:$D$231,0)),"not in table")) | E34: =IF(ISNUMBER(D34),2*D34,"") | F34: =IF(ISNUMBER(E34),MAX(1,INT('Truck Requirement'!$B$4/E34)),"") | G34: =IF(AND(ISNUMBER(F34),C34<>""),C34/F34,"") | H34: =IF(ISNUMBER(G34),ROUNDUP(G34,0),"")
A35: Total | C35: =SUM(C5:C34) | G35: =SUM(G5:G34) | H35: =SUM(H5:H34)

Sheet Revenue Planner
A1: Revenue planner — what each route earns with the trucks allocated to it
A2: Pick the client and route, enter trips per month and your price per trip (yellow). Trucks follow the same rotation as the Order Planner. Revenue per truck-day lets you compare routes fairly: it is what one truck earns for each day it is tied up on that route.
A4: Client | B4: Route (turnaround key) | C4: Trips per month | D4: Price per trip (₦) | E4: One-leg days | F4: Round-trip days | G4: Trips one truck can do per month | H4: Truck use (exact) | I4: Trucks needed | J4: Monthly revenue (₦) | K4: Revenue per truck per month (₦) | L4: Revenue per truck-day (₦) | M4: Spare trips with these trucks | N4: Market avg price Jul–Sep (₦) | O4: Highest price Jul–Sep (₦) | P4: Your price vs market avg | R4: Totals by client
A5: Jamara | B5: ABUJA>LAGOS | C5: 4 | D5: 2693000 | E5: =IF(B5="","",IFERROR(INDEX('Turnaround Table'!$C$5:$C$231,MATCH(B5,'Turnaround Table'!$D$5:$D$231,0)),"not in table")) | F5: =IF(ISNUMBER(E5),2*E5,"") | G5: =IF(ISNUMBER(F5),MAX(1,INT('Truck Requirement'!$B$4/F5)),"") | H5: =IF(AND(ISNUMBER(G5),C5<>""),C5/G5,"") | I5: =IF(ISNUMBER(H5),ROUNDUP(H5,0),"") | J5: =IF(AND(C5<>"",D5<>""),C5*D5,"") | K5: =IF(AND(ISNUMBER(J5),ISNUMBER(I5)),IF(I5=0,"",J5/I5),"") | L5: =IF(AND(ISNUMBER(D5),ISNUMBER(F5)),D5/F5,"") | M5: =IF(ISNUMBER(I5),I5*G5-C5,"") | N5: =IF(B5="","",IFERROR(INDEX('Route Prices'!$F$5:$F$103,MATCH(B5,'Route Prices'!$A$5:$A$103,0)),"")) | O5: =IF(B5="","",IFERROR(INDEX('Route Prices'!$G$5:$G$103,MATCH(B5,'Route Prices'!$A$5:$A$103,0)),"")) | P5: =IF(AND(ISNUMBER(D5),ISNUMBER(N5)),IF(N5=0,"",D5/N5-1),"") | R5: Client | S5: Trips per month | T5: Trucks needed (shared across routes) | U5: Monthly revenue (₦) | V5: Revenue per truck per month (₦) | W5: Yearly revenue (₦)
A6: Jamara | B6: PORT HARCOURT>LAGOS | C6: 6 | D6: 2491000 | E6: =IF(B6="","",IFERROR(INDEX('Turnaround Table'!$C$5:$C$231,MATCH(B6,'Turnaround Table'!$D$5:$D$231,0)),"not in table")) | F6: =IF(ISNUMBER(E6),2*E6,"") | G6: =IF(ISNUMBER(F6),MAX(1,INT('Truck Requirement'!$B$4/F6)),"") | H6: =IF(AND(ISNUMBER(G6),C6<>""),C6/G6,"") | I6: =IF(ISNUMBER(H6),ROUNDUP(H6,0),"") | J6: =IF(AND(C6<>"",D6<>""),C6*D6,"") | K6: =IF(AND(ISNUMBER(J6),ISNUMBER(I6)),IF(I6=0,"",J6/I6),"") | L6: =IF(AND(ISNUMBER(D6),ISNUMBER(F6)),D6/F6,"") | M6: =IF(ISNUMBER(I6),I6*G6-C6,"") | N6: =IF(B6="","",IFERROR(INDEX('Route Prices'!$F$5:$F$103,MATCH(B6,'Route Prices'!$A$5:$A$103,0)),"")) | O6: =IF(B6="","",IFERROR(INDEX('Route Prices'!$G$5:$G$103,MATCH(B6,'Route Prices'!$A$5:$A$103,0)),"")) | P6: =IF(AND(ISNUMBER(D6),ISNUMBER(N6)),IF(N6=0,"",D6/N6-1),"") | R6: Jamara | S6: =IF(R6="","",SUMIF($A$5:$A$34,R6,$C$5:$C$34)) | T6: =IF(R6="","",ROUNDUP(SUMIF($A$5:$A$34,R6,$H$5:$H$34),0)) | U6: =IF(R6="","",SUMIF($A$5:$A$34,R6,$J$5:$J$34)) | V6: =IF(OR(R6="",T6=0),"",U6/T6) | W6: =IF(R6="","",U6*12)
A7: Jamara | B7: KANO>LAGOS | C7: 4 | D7: 3775000 | E7: =IF(B7="","",IFERROR(INDEX('Turnaround Table'!$C$5:$C$231,MATCH(B7,'Turnaround Table'!$D$5:$D$231,0)),"not in table")) | F7: =IF(ISNUMBER(E7),2*E7,"") | G7: =IF(ISNUMBER(F7),MAX(1,INT('Truck Requirement'!$B$4/F7)),"") | H7: =IF(AND(ISNUMBER(G7),C7<>""),C7/G7,"") | I7: =IF(ISNUMBER(H7),ROUNDUP(H7,0),"") | J7: =IF(AND(C7<>"",D7<>""),C7*D7,"") | K7: =IF(AND(ISNUMBER(J7),ISNUMBER(I7)),IF(I7=0,"",J7/I7),"") | L7: =IF(AND(ISNUMBER(D7),ISNUMBER(F7)),D7/F7,"") | M7: =IF(ISNUMBER(I7),I7*G7-C7,"") | N7: =IF(B7="","",IFERROR(INDEX('Route Prices'!$F$5:$F$103,MATCH(B7,'Route Prices'!$A$5:$A$103,0)),"")) | O7: =IF(B7="","",IFERROR(INDEX('Route Prices'!$G$5:$G$103,MATCH(B7,'Route Prices'!$A$5:$A$103,0)),"")) | P7: =IF(AND(ISNUMBER(D7),ISNUMBER(N7)),IF(N7=0,"",D7/N7-1),"") | S7: =IF(R7="","",SUMIF($A$5:$A$34,R7,$C$5:$C$34)) | T7: =IF(R7="","",ROUNDUP(SUMIF($A$5:$A$34,R7,$H$5:$H$34),0)) | U7: =IF(R7="","",SUMIF($A$5:$A$34,R7,$J$5:$J$34)) | V7: =IF(OR(R7="",T7=0),"",U7/T7) | W7: =IF(R7="","",U7*12)
E8: =IF(B8="","",IFERROR(INDEX('Turnaround Table'!$C$5:$C$231,MATCH(B8,'Turnaround Table'!$D$5:$D$231,0)),"not in table")) | F8: =IF(ISNUMBER(E8),2*E8,"") | G8: =IF(ISNUMBER(F8),MAX(1,INT('Truck Requirement'!$B$4/F8)),"") | H8: =IF(AND(ISNUMBER(G8),C8<>""),C8/G8,"") | I8: =IF(ISNUMBER(H8),ROUNDUP(H8,0),"") | J8: =IF(AND(C8<>"",D8<>""),C8*D8,"") | K8: =IF(AND(ISNUMBER(J8),ISNUMBER(I8)),IF(I8=0,"",J8/I8),"") | L8: =IF(AND(ISNUMBER(D8),ISNUMBER(F8)),D8/F8,"") | M8: =IF(ISNUMBER(I8),I8*G8-C8,"") | N8: =IF(B8="","",IFERROR(INDEX('Route Prices'!$F$5:$F$103,MATCH(B8,'Route Prices'!$A$5:$A$103,0)),"")) | O8: =IF(B8="","",IFERROR(INDEX('Route Prices'!$G$5:$G$103,MATCH(B8,'Route Prices'!$A$5:$A$103,0)),"")) | P8: =IF(AND(ISNUMBER(D8),ISNUMBER(N8)),IF(N8=0,"",D8/N8-1),"") | S8: =IF(R8="","",SUMIF($A$5:$A$34,R8,$C$5:$C$34)) | T8: =IF(R8="","",ROUNDUP(SUMIF($A$5:$A$34,R8,$H$5:$H$34),0)) | U8: =IF(R8="","",SUMIF($A$5:$A$34,R8,$J$5:$J$34)) | V8: =IF(OR(R8="",T8=0),"",U8/T8) | W8: =IF(R8="","",U8*12)
E9: =IF(B9="","",IFERROR(INDEX('Turnaround Table'!$C$5:$C$231,MATCH(B9,'Turnaround Table'!$D$5:$D$231,0)),"not in table")) | F9: =IF(ISNUMBER(E9),2*E9,"") | G9: =IF(ISNUMBER(F9),MAX(1,INT('Truck Requirement'!$B$4/F9)),"") | H9: =IF(AND(ISNUMBER(G9),C9<>""),C9/G9,"") | I9: =IF(ISNUMBER(H9),ROUNDUP(H9,0),"") | J9: =IF(AND(C9<>"",D9<>""),C9*D9,"") | K9: =IF(AND(ISNUMBER(J9),ISNUMBER(I9)),IF(I9=0,"",J9/I9),"") | L9: =IF(AND(ISNUMBER(D9),ISNUMBER(F9)),D9/F9,"") | M9: =IF(ISNUMBER(I9),I9*G9-C9,"") | N9: =IF(B9="","",IFERROR(INDEX('Route Prices'!$F$5:$F$103,MATCH(B9,'Route Prices'!$A$5:$A$103,0)),"")) | O9: =IF(B9="","",IFERROR(INDEX('Route Prices'!$G$5:$G$103,MATCH(B9,'Route Prices'!$A$5:$A$103,0)),"")) | P9: =IF(AND(ISNUMBER(D9),ISNUMBER(N9)),IF(N9=0,"",D9/N9-1),"") | S9: =IF(R9="","",SUMIF($A$5:$A$34,R9,$C$5:$C$34)) | T9: =IF(R9="","",ROUNDUP(SUMIF($A$5:$A$34,R9,$H$5:$H$34),0)) | U9: =IF(R9="","",SUMIF($A$5:$A$34,R9,$J$5:$J$34)) | V9: =IF(OR(R9="",T9=0),"",U9/T9) | W9: =IF(R9="","",U9*12)
E10: =IF(B10="","",IFERROR(INDEX('Turnaround Table'!$C$5:$C$231,MATCH(B10,'Turnaround Table'!$D$5:$D$231,0)),"not in table")) | F10: =IF(ISNUMBER(E10),2*E10,"") | G10: =IF(ISNUMBER(F10),MAX(1,INT('Truck Requirement'!$B$4/F10)),"") | H10: =IF(AND(ISNUMBER(G10),C10<>""),C10/G10,"") | I10: =IF(ISNUMBER(H10),ROUNDUP(H10,0),"") | J10: =IF(AND(C10<>"",D10<>""),C10*D10,"") | K10: =IF(AND(ISNUMBER(J10),ISNUMBER(I10)),IF(I10=0,"",J10/I10),"") | L10: =IF(AND(ISNUMBER(D10),ISNUMBER(F10)),D10/F10,"") | M10: =IF(ISNUMBER(I10),I10*G10-C10,"") | N10: =IF(B10="","",IFERROR(INDEX('Route Prices'!$F$5:$F$103,MATCH(B10,'Route Prices'!$A$5:$A$103,0)),"")) | O10: =IF(B10="","",IFERROR(INDEX('Route Prices'!$G$5:$G$103,MATCH(B10,'Route Prices'!$A$5:$A$103,0)),"")) | P10: =IF(AND(ISNUMBER(D10),ISNUMBER(N10)),IF(N10=0,"",D10/N10-1),"") | S10: =IF(R10="","",SUMIF($A$5:$A$34,R10,$C$5:$C$34)) | T10: =IF(R10="","",ROUNDUP(SUMIF($A$5:$A$34,R10,$H$5:$H$34),0)) | U10: =IF(R10="","",SUMIF($A$5:$A$34,R10,$J$5:$J$34)) | V10: =IF(OR(R10="",T10=0),"",U10/T10) | W10: =IF(R10="","",U10*12)
E11: =IF(B11="","",IFERROR(INDEX('Turnaround Table'!$C$5:$C$231,MATCH(B11,'Turnaround Table'!$D$5:$D$231,0)),"not in table")) | F11: =IF(ISNUMBER(E11),2*E11,"") | G11: =IF(ISNUMBER(F11),MAX(1,INT('Truck Requirement'!$B$4/F11)),"") | H11: =IF(AND(ISNUMBER(G11),C11<>""),C11/G11,"") | I11: =IF(ISNUMBER(H11),ROUNDUP(H11,0),"") | J11: =IF(AND(C11<>"",D11<>""),C11*D11,"") | K11: =IF(AND(ISNUMBER(J11),ISNUMBER(I11)),IF(I11=0,"",J11/I11),"") | L11: =IF(AND(ISNUMBER(D11),ISNUMBER(F11)),D11/F11,"") | M11: =IF(ISNUMBER(I11),I11*G11-C11,"") | N11: =IF(B11="","",IFERROR(INDEX('Route Prices'!$F$5:$F$103,MATCH(B11,'Route Prices'!$A$5:$A$103,0)),"")) | O11: =IF(B11="","",IFERROR(INDEX('Route Prices'!$G$5:$G$103,MATCH(B11,'Route Prices'!$A$5:$A$103,0)),"")) | P11: =IF(AND(ISNUMBER(D11),ISNUMBER(N11)),IF(N11=0,"",D11/N11-1),"") | S11: =IF(R11="","",SUMIF($A$5:$A$34,R11,$C$5:$C$34)) | T11: =IF(R11="","",ROUNDUP(SUMIF($A$5:$A$34,R11,$H$5:$H$34),0)) | U11: =IF(R11="","",SUMIF($A$5:$A$34,R11,$J$5:$J$34)) | V11: =IF(OR(R11="",T11=0),"",U11/T11) | W11: =IF(R11="","",U11*12)
E12: =IF(B12="","",IFERROR(INDEX('Turnaround Table'!$C$5:$C$231,MATCH(B12,'Turnaround Table'!$D$5:$D$231,0)),"not in table")) | F12: =IF(ISNUMBER(E12),2*E12,"") | G12: =IF(ISNUMBER(F12),MAX(1,INT('Truck Requirement'!$B$4/F12)),"") | H12: =IF(AND(ISNUMBER(G12),C12<>""),C12/G12,"") | I12: =IF(ISNUMBER(H12),ROUNDUP(H12,0),"") | J12: =IF(AND(C12<>"",D12<>""),C12*D12,"") | K12: =IF(AND(ISNUMBER(J12),ISNUMBER(I12)),IF(I12=0,"",J12/I12),"") | L12: =IF(AND(ISNUMBER(D12),ISNUMBER(F12)),D12/F12,"") | M12: =IF(ISNUMBER(I12),I12*G12-C12,"") | N12: =IF(B12="","",IFERROR(INDEX('Route Prices'!$F$5:$F$103,MATCH(B12,'Route Prices'!$A$5:$A$103,0)),"")) | O12: =IF(B12="","",IFERROR(INDEX('Route Prices'!$G$5:$G$103,MATCH(B12,'Route Prices'!$A$5:$A$103,0)),"")) | P12: =IF(AND(ISNUMBER(D12),ISNUMBER(N12)),IF(N12=0,"",D12/N12-1),"") | S12: =IF(R12="","",SUMIF($A$5:$A$34,R12,$C$5:$C$34)) | T12: =IF(R12="","",ROUNDUP(SUMIF($A$5:$A$34,R12,$H$5:$H$34),0)) | U12: =IF(R12="","",SUMIF($A$5:$A$34,R12,$J$5:$J$34)) | V12: =IF(OR(R12="",T12=0),"",U12/T12) | W12: =IF(R12="","",U12*12)
E13: =IF(B13="","",IFERROR(INDEX('Turnaround Table'!$C$5:$C$231,MATCH(B13,'Turnaround Table'!$D$5:$D$231,0)),"not in table")) | F13: =IF(ISNUMBER(E13),2*E13,"") | G13: =IF(ISNUMBER(F13),MAX(1,INT('Truck Requirement'!$B$4/F13)),"") | H13: =IF(AND(ISNUMBER(G13),C13<>""),C13/G13,"") | I13: =IF(ISNUMBER(H13),ROUNDUP(H13,0),"") | J13: =IF(AND(C13<>"",D13<>""),C13*D13,"") | K13: =IF(AND(ISNUMBER(J13),ISNUMBER(I13)),IF(I13=0,"",J13/I13),"") | L13: =IF(AND(ISNUMBER(D13),ISNUMBER(F13)),D13/F13,"") | M13: =IF(ISNUMBER(I13),I13*G13-C13,"") | N13: =IF(B13="","",IFERROR(INDEX('Route Prices'!$F$5:$F$103,MATCH(B13,'Route Prices'!$A$5:$A$103,0)),"")) | O13: =IF(B13="","",IFERROR(INDEX('Route Prices'!$G$5:$G$103,MATCH(B13,'Route Prices'!$A$5:$A$103,0)),"")) | P13: =IF(AND(ISNUMBER(D13),ISNUMBER(N13)),IF(N13=0,"",D13/N13-1),"") | S13: =IF(R13="","",SUMIF($A$5:$A$34,R13,$C$5:$C$34)) | T13: =IF(R13="","",ROUNDUP(SUMIF($A$5:$A$34,R13,$H$5:$H$34),0)) | U13: =IF(R13="","",SUMIF($A$5:$A$34,R13,$J$5:$J$34)) | V13: =IF(OR(R13="",T13=0),"",U13/T13) | W13: =IF(R13="","",U13*12)
E14: =IF(B14="","",IFERROR(INDEX('Turnaround Table'!$C$5:$C$231,MATCH(B14,'Turnaround Table'!$D$5:$D$231,0)),"not in table")) | F14: =IF(ISNUMBER(E14),2*E14,"") | G14: =IF(ISNUMBER(F14),MAX(1,INT('Truck Requirement'!$B$4/F14)),"") | H14: =IF(AND(ISNUMBER(G14),C14<>""),C14/G14,"") | I14: =IF(ISNUMBER(H14),ROUNDUP(H14,0),"") | J14: =IF(AND(C14<>"",D14<>""),C14*D14,"") | K14: =IF(AND(ISNUMBER(J14),ISNUMBER(I14)),IF(I14=0,"",J14/I14),"") | L14: =IF(AND(ISNUMBER(D14),ISNUMBER(F14)),D14/F14,"") | M14: =IF(ISNUMBER(I14),I14*G14-C14,"") | N14: =IF(B14="","",IFERROR(INDEX('Route Prices'!$F$5:$F$103,MATCH(B14,'Route Prices'!$A$5:$A$103,0)),"")) | O14: =IF(B14="","",IFERROR(INDEX('Route Prices'!$G$5:$G$103,MATCH(B14,'Route Prices'!$A$5:$A$103,0)),"")) | P14: =IF(AND(ISNUMBER(D14),ISNUMBER(N14)),IF(N14=0,"",D14/N14-1),"") | S14: =IF(R14="","",SUMIF($A$5:$A$34,R14,$C$5:$C$34)) | T14: =IF(R14="","",ROUNDUP(SUMIF($A$5:$A$34,R14,$H$5:$H$34),0)) | U14: =IF(R14="","",SUMIF($A$5:$A$34,R14,$J$5:$J$34)) | V14: =IF(OR(R14="",T14=0),"",U14/T14) | W14: =IF(R14="","",U14*12)
E15: =IF(B15="","",IFERROR(INDEX('Turnaround Table'!$C$5:$C$231,MATCH(B15,'Turnaround Table'!$D$5:$D$231,0)),"not in table")) | F15: =IF(ISNUMBER(E15),2*E15,"") | G15: =IF(ISNUMBER(F15),MAX(1,INT('Truck Requirement'!$B$4/F15)),"") | H15: =IF(AND(ISNUMBER(G15),C15<>""),C15/G15,"") | I15: =IF(ISNUMBER(H15),ROUNDUP(H15,0),"") | J15: =IF(AND(C15<>"",D15<>""),C15*D15,"") | K15: =IF(AND(ISNUMBER(J15),ISNUMBER(I15)),IF(I15=0,"",J15/I15),"") | L15: =IF(AND(ISNUMBER(D15),ISNUMBER(F15)),D15/F15,"") | M15: =IF(ISNUMBER(I15),I15*G15-C15,"") | N15: =IF(B15="","",IFERROR(INDEX('Route Prices'!$F$5:$F$103,MATCH(B15,'Route Prices'!$A$5:$A$103,0)),"")) | O15: =IF(B15="","",IFERROR(INDEX('Route Prices'!$G$5:$G$103,MATCH(B15,'Route Prices'!$A$5:$A$103,0)),"")) | P15: =IF(AND(ISNUMBER(D15),ISNUMBER(N15)),IF(N15=0,"",D15/N15-1),"") | S15: =IF(R15="","",SUMIF($A$5:$A$34,R15,$C$5:$C$34)) | T15: =IF(R15="","",ROUNDUP(SUMIF($A$5:$A$34,R15,$H$5:$H$34),0)) | U15: =IF(R15="","",SUMIF($A$5:$A$34,R15,$J$5:$J$34)) | V15: =IF(OR(R15="",T15=0),"",U15/T15) | W15: =IF(R15="","",U15*12)
