Workbook
Name \0: #REF!
Name \X: #REF!
Name _311_H: #REF!
Name _BOM2: #REF!
Name _COL1: #REF!
Name _DAT1: #REF!
Name _DAT2: #REF!
Name _DAT3: #REF!
Name _DAT4: #REF!
Name _DAT5: #REF!
Name _DAT6: #REF!
Name _DAT7: #REF!
Name _DAT8: #REF!
Name _DAT9: #REF!
Name _hdr1: #REF!
Name _hdr2: #REF!
Name _hdr22: #REF!
Name _MAK1: #REF!
Name _MAK2: #REF!
Name _MAK3: #REF!
Name _MAK4: #REF!
Name _ONE1: #REF!
Name _ROW1: #REF!
Name _SIX1: #REF!
Name _TEN1: #REF!
Name _TWO1: #REF!
Name ○: #REF!
Name a: #REF!
Name A11A: #REF!
Name A11B: #REF!
Name A12A: #REF!
Name A12B: #REF!
Name A13A: #REF!
Name A13B: #REF!
Name A14A: #REF!
Name A14B: #REF!
Name A15A: #REF!
Name A15B: #REF!
Name A16A: #REF!
Name A16B: #REF!
Name A17A: #REF!
Name A17B: #REF!
Name A18A: #REF!
Name A18B: #REF!
Name A19A: #REF!
Name A19B: #REF!
Name A20A: #REF!
Name A20B: #REF!
Name A21A: #REF!
Name A21B: #REF!
Name A22A: #REF!
Name A22B: #REF!
Name A23A: #REF!
Name A23B: #REF!
Name A24A: #REF!
Name A24B: #REF!
Name A25A: #REF!
Name A25B: #REF!
Name AA: #REF!
Name aaaa: #REF!

Sheet Asset Code
A1: Asset code | B1: Plate Number | C1: Asset Name | D1: Tonnage | E1: Body Size | F1: Type | G1: Cost Center | H1: Cost Center Name
A2: MVEH-000266 | B2: T2404LA | C2: Volswagen Titan Tractor 18-310 Head | D2: 25T | E2: FLAT | F2: Tractor Head | G2: =_xlfn.XLOOKUP(A2,'[3]Budgets 2027'!I$3:I$759,'[3]Budgets 2027'!Q$3:Q$759) -> CC046 | H2: =_xlfn.XLOOKUP(A2,'[3]Budgets 2027'!I$3:I$759,'[3]Budgets 2027'!R$3:R$759) -> Flat Trucks Logistics
A3: MVEH-000267 | B3: T2486LA | C3: Volswagen Titan Tractor 18-310 Head | D3: 25T | E3: FLAT | F3: Tractor Head | G3: =_xlfn.XLOOKUP(A3,'[3]Budgets 2027'!I$3:I$759,'[3]Budgets 2027'!Q$3:Q$759) -> CC046 | H3: =_xlfn.XLOOKUP(A3,'[3]Budgets 2027'!I$3:I$759,'[3]Budgets 2027'!R$3:R$759) -> Flat Trucks Logistics
A4: MVEH-000269 | B4: T2490LA | C4: Volswagen Titan Tractor 18-310 Head | D4: 25T | E4: FLAT | F4: Tractor Head | G4: =_xlfn.XLOOKUP(A4,'[3]Budgets 2027'!I$3:I$759,'[3]Budgets 2027'!Q$3:Q$759) -> CC046 | H4: =_xlfn.XLOOKUP(A4,'[3]Budgets 2027'!I$3:I$759,'[3]Budgets 2027'!R$3:R$759) -> Flat Trucks Logistics
A5: MVEH-000271 | B5: T2407LA | C5: Volswagen Titan Tractor 18-310 Head | D5: 25T | E5: FLAT | F5: Tractor Head | G5: =_xlfn.XLOOKUP(A5,'[3]Budgets 2027'!I$3:I$759,'[3]Budgets 2027'!Q$3:Q$759) -> CC046 | H5: =_xlfn.XLOOKUP(A5,'[3]Budgets 2027'!I$3:I$759,'[3]Budgets 2027'!R$3:R$759) -> Flat Trucks Logistics
A6: MVEH-000273 | B6: T2485LA | C6: Volswagen Titan Tractor 18-310 Head | D6: 30T | E6: FLAT | F6: Tractor Head | G6: =_xlfn.XLOOKUP(A6,'[3]Budgets 2027'!I$3:I$759,'[3]Budgets 2027'!Q$3:Q$759) -> CC046 | H6: =_xlfn.XLOOKUP(A6,'[3]Budgets 2027'!I$3:I$759,'[3]Budgets 2027'!R$3:R$759) -> Flat Trucks Logistics
A7: MVEH-000276 | B7: T2412LA | C7: Volswagen Titan Tractor 18-310 Head | D7: 25T | E7: FLAT | F7: Tractor Head | G7: =_xlfn.XLOOKUP(A7,'[3]Budgets 2027'!I$3:I$759,'[3]Budgets 2027'!Q$3:Q$759) -> CC046 | H7: =_xlfn.XLOOKUP(A7,'[3]Budgets 2027'!I$3:I$759,'[3]Budgets 2027'!R$3:R$759) -> Flat Trucks Logistics
A8: MVEH-000283 | B8: T2420LA | C8: Volswagen Titan Tractor 18-310 Head | D8: 25T | E8: FLAT | F8: Tractor Head | G8: =_xlfn.XLOOKUP(A8,'[3]Budgets 2027'!I$3:I$759,'[3]Budgets 2027'!Q$3:Q$759) -> CC046 | H8: =_xlfn.XLOOKUP(A8,'[3]Budgets 2027'!I$3:I$759,'[3]Budgets 2027'!R$3:R$759) -> Flat Trucks Logistics
A9: MVEH-000326 | B9: EPE531YD | C9: Mercedes Benz Diesel Truck | D9: 15T | E9: TANKER | F9: Tractor Head | G9: =_xlfn.XLOOKUP(A9,'[3]Budgets 2027'!I$3:I$759,'[3]Budgets 2027'!Q$3:Q$759) -> CC037 | H9: =_xlfn.XLOOKUP(A9,'[3]Budgets 2027'!I$3:I$759,'[3]Budgets 2027'!R$3:R$759) -> General Overhead
A10: MVEH-000130 | B10: T2418LA | C10: Volswagen Titan Tractor 18-310 Head | D10: 25T | E10: FLAT | F10: Tractor Head | G10: =_xlfn.XLOOKUP(A10,'[3]Budgets 2027'!I$3:I$759,'[3]Budgets 2027'!Q$3:Q$759) -> CC046 | H10: =_xlfn.XLOOKUP(A10,'[3]Budgets 2027'!I$3:I$759,'[3]Budgets 2027'!R$3:R$759) -> Flat Trucks Logistics
A11: MVEH-000131 | B11: T2489LA | C11: Volswagen Titan Tractor 18-310 Head | D11: 25T | E11: FLAT | F11: Tractor Head | G11: =_xlfn.XLOOKUP(A11,'[3]Budgets 2027'!I$3:I$759,'[3]Budgets 2027'!Q$3:Q$759) -> CC046 | H11: =_xlfn.XLOOKUP(A11,'[3]Budgets 2027'!I$3:I$759,'[3]Budgets 2027'!R$3:R$759) -> Flat Trucks Logistics
A12: MVEH-000132 | B12: T2421LA | C12: Volswagen Titan Tractor 18-310 Head | D12: 25T | E12: FLAT | F12: Tractor Head | G12: =_xlfn.XLOOKUP(A12,'[3]Budgets 2027'!I$3:I$759,'[3]Budgets 2027'!Q$3:Q$759) -> CC046 | H12: =_xlfn.XLOOKUP(A12,'[3]Budgets 2027'!I$3:I$759,'[3]Budgets 2027'!R$3:R$759) -> Flat Trucks Logistics
A13: MVEH-000142 | B13: T2419LA | C13: Volswagen Titan Tractor 18-310 | D13: 25T | E13: FLAT | F13: Tractor Head | G13: =_xlfn.XLOOKUP(A13,'[3]Budgets 2027'!I$3:I$759,'[3]Budgets 2027'!Q$3:Q$759) -> CC046 | H13: =_xlfn.XLOOKUP(A13,'[3]Budgets 2027'!I$3:I$759,'[3]Budgets 2027'!R$3:R$759) -> Flat Trucks Logistics
... A68: MVEH-000146 | B68: T2413LA | C68: T 2413 LA 4*2Cargo Truck | D68: 8T | E68: 25FT | F68: Canter | G68: =_xlfn.XLOOKUP(A68,'[3]Budgets 2027'!I$3:I$759,'[3]Budgets 2027'!Q$3:Q$759) -> CC047 | H68: =_xlfn.XLOOKUP(A68,'[3]Budgets 2027'!I$3:I$759,'[3]Budgets 2027'!R$3:R$759) -> Closed Body Logistics
A69: MVEH-000134 | B69: 0 | C69: Flat Trailer single Axel - 30T | D69: =_xlfn.XLOOKUP(A69,'[4]Fleet Master'!D$3:D$52,'[4]Fleet Master'!F$3:F$52) -> 30T | E69: 102-45T | F69: BOX BODY | G69: =_xlfn.XLOOKUP(A69,'[3]Budgets 2027'!I$3:I$759,'[3]Budgets 2027'!Q$3:Q$759) -> CC046 | H69: =_xlfn.XLOOKUP(A69,'[3]Budgets 2027'!I$3:I$759,'[3]Budgets 2027'!R$3:R$759) -> Flat Trucks Logistics
A70: MVEH-000135 | B70: 0 | C70: Flat Trailer single Axel - 30T (double not yet acquired) | D70: =_xlfn.XLOOKUP(A70,'[4]Fleet Master'!D$3:D$52,'[4]Fleet Master'!F$3:F$52) -> 30T | E70: 102-30T | F70: BOX BODY | G70: =_xlfn.XLOOKUP(A70,'[3]Budgets 2027'!I$3:I$759,'[3]Budgets 2027'!Q$3:Q$759) -> CC046 | H70: =_xlfn.XLOOKUP(A70,'[3]Budgets 2027'!I$3:I$759,'[3]Budgets 2027'!R$3:R$759) -> Flat Trucks Logistics
A71: MVEH-000265 | B71: 0 | C71: FLAT TRAILER SINGLE AXEL-30T | D71: 30T | E71: FLAT | F71: Flat Trailer | G71: =_xlfn.XLOOKUP(A71,'[3]Budgets 2027'!I$3:I$759,'[3]Budgets 2027'!Q$3:Q$759) -> CC046 | H71: =_xlfn.XLOOKUP(A71,'[3]Budgets 2027'!I$3:I$759,'[3]Budgets 2027'!R$3:R$759) -> Flat Trucks Logistics
A72: MVEH-000268 | B72: 0 | C72: Flat Trailer single Axel - 30T | D72: 30T | E72: FLAT | F72: Flat Trailer | G72: =_xlfn.XLOOKUP(A72,'[3]Budgets 2027'!I$3:I$759,'[3]Budgets 2027'!Q$3:Q$759) -> CC046 | H72: =_xlfn.XLOOKUP(A72,'[3]Budgets 2027'!I$3:I$759,'[3]Budgets 2027'!R$3:R$759) -> Flat Trucks Logistics
A73: MVEH-000279 | B73: 0 | C73: Flat Trailer single Axel - 30T | D73: =_xlfn.XLOOKUP(A73,'[4]Fleet Master'!D$3:D$52,'[4]Fleet Master'!F$3:F$52) -> 30T | E73: FLAT | F73: Flat Trailer | G73: =_xlfn.XLOOKUP(A73,'[3]Budgets 2027'!I$3:I$759,'[3]Budgets 2027'!Q$3:Q$759) -> CC046 | H73: =_xlfn.XLOOKUP(A73,'[3]Budgets 2027'!I$3:I$759,'[3]Budgets 2027'!R$3:R$759) -> Flat Trucks Logistics
A74: MVEH-000292 | B74: 0 | C74: FLAT TRAILER SINGLE AXEL-30T | D74: =_xlfn.XLOOKUP(A74,'[4]Fleet Master'!D$3:D$52,'[4]Fleet Master'!F$3:F$52) -> 30T | E74: FLAT | F74: Flat Trailer | G74: =_xlfn.XLOOKUP(A74,'[3]Budgets 2027'!I$3:I$759,'[3]Budgets 2027'!Q$3:Q$759) -> CC046 | H74: =_xlfn.XLOOKUP(A74,'[3]Budgets 2027'!I$3:I$759,'[3]Budgets 2027'!R$3:R$759) -> Flat Trucks Logistics
A75: MVEH-000293 | B75: 0 | C75: FLAT TRAILER SINGLE AXEL-30T | D75: =_xlfn.XLOOKUP(A75,'[4]Fleet Master'!D$3:D$52,'[4]Fleet Master'!F$3:F$52) -> 30T | E75: 102-30T | F75: BOX BODY | G75: =_xlfn.XLOOKUP(A75,'[3]Budgets 2027'!I$3:I$759,'[3]Budgets 2027'!Q$3:Q$759) -> CC046 | H75: =_xlfn.XLOOKUP(A75,'[3]Budgets 2027'!I$3:I$759,'[3]Budgets 2027'!R$3:R$759) -> Flat Trucks Logistics
A76: MVEH-000303 | B76: 0 | C76: Flat Trailer single Axel - 30T | D76: =_xlfn.XLOOKUP(A76,'[4]Fleet Master'!D$3:D$52,'[4]Fleet Master'!F$3:F$52) -> 30T | E76: 102-45T | F76: BOX BODY | G76: =_xlfn.XLOOKUP(A76,'[3]Budgets 2027'!I$3:I$759,'[3]Budgets 2027'!Q$3:Q$759) -> CC046 | H76: =_xlfn.XLOOKUP(A76,'[3]Budgets 2027'!I$3:I$759,'[3]Budgets 2027'!R$3:R$759) -> Flat Trucks Logistics
A77: MVEH-000362 | B77: 0 | C77: Flat Trailer single Axel - 30T | D77: =_xlfn.XLOOKUP(A77,'[4]Fleet Master'!D$3:D$52,'[4]Fleet Master'!F$3:F$52) -> 30T | E77: FLAT | F77: Flat Trailer | G77: =_xlfn.XLOOKUP(A77,'[3]Budgets 2027'!I$3:I$759,'[3]Budgets 2027'!Q$3:Q$759) -> CC046 | H77: =_xlfn.XLOOKUP(A77,'[3]Budgets 2027'!I$3:I$759,'[3]Budgets 2027'!R$3:R$759) -> Flat Trucks Logistics
A78: MVEH-000133 | B78: 0 | C78: Flat Trailer single Axel - 30T | D78: =_xlfn.XLOOKUP(A78,'[4]Fleet Master'!D$3:D$52,'[4]Fleet Master'!F$3:F$52) -> 30T | E78: 102-30T | F78: BOX BODY | G78: =_xlfn.XLOOKUP(A78,'[3]Budgets 2027'!I$3:I$759,'[3]Budgets 2027'!Q$3:Q$759) -> CC046 | H78: =_xlfn.XLOOKUP(A78,'[3]Budgets 2027'!I$3:I$759,'[3]Budgets 2027'!R$3:R$759) -> Flat Trucks Logistics
A79: MVEH-000138 | B79: 0 | C79: Flat Trailer single Axel - 30T | D79: =_xlfn.XLOOKUP(A79,'[4]Fleet Master'!D$3:D$52,'[4]Fleet Master'!F$3:F$52) -> 30T | E79: FLAT | F79: Flat Trailer | G79: =_xlfn.XLOOKUP(A79,'[3]Budgets 2027'!I$3:I$759,'[3]Budgets 2027'!Q$3:Q$759) -> CC046 | H79: =_xlfn.XLOOKUP(A79,'[3]Budgets 2027'!I$3:I$759,'[3]Budgets 2027'!R$3:R$759) -> Flat Trucks Logistics
A80: MVEH-000139 | B80: 0 | C80: Flat Trailer single Axel - 30T (double not yet acquired) | D80: =_xlfn.XLOOKUP(A80,'[4]Fleet Master'!D$3:D$52,'[4]Fleet Master'!F$3:F$52) -> 30T | E80: FLAT | F80: Flat Trailer | G80: =_xlfn.XLOOKUP(A80,'[3]Budgets 2027'!I$3:I$759,'[3]Budgets 2027'!Q$3:Q$759) -> CC046 | H80: =_xlfn.XLOOKUP(A80,'[3]Budgets 2027'!I$3:I$759,'[3]Budgets 2027'!R$3:R$759) -> Flat Trucks Logistics
A81: MVEH-000140 | B81: 0 | C81: Flat Trailer single Axel - 30T | D81: =_xlfn.XLOOKUP(A81,'[4]Fleet Master'!D$3:D$52,'[4]Fleet Master'!F$3:F$52) -> 35T | E81: 102-30T | F81: BOX BODY | G81: =_xlfn.XLOOKUP(A81,'[3]Budgets 2027'!I$3:I$759,'[3]Budgets 2027'!Q$3:Q$759) -> CC046 | H81: =_xlfn.XLOOKUP(A81,'[3]Budgets 2027'!I$3:I$759,'[3]Budgets 2027'!R$3:R$759) -> Flat Trucks Logistics
A82: MVEH-000270 | B82: 0 | C82: Flat Trailer single Axel - 30T | D82: =_xlfn.XLOOKUP(A82,'[4]Fleet Master'!D$3:D$52,'[4]Fleet Master'!F$3:F$52) -> 30T | E82: FLAT | F82: Flat Trailer | G82: =_xlfn.XLOOKUP(A82,'[3]Budgets 2027'!I$3:I$759,'[3]Budgets 2027'!Q$3:Q$759) -> CC046 | H82: =_xlfn.XLOOKUP(A82,'[3]Budgets 2027'!I$3:I$759,'[3]Budgets 2027'!R$3:R$759) -> Flat Trucks Logistics
A83: MVEH-000272 | B83: 0 | C83: Flat Trailer single Axel - 30T | D83: 30T | E83: FLAT | F83: Flat Trailer | G83: =_xlfn.XLOOKUP(A83,'[3]Budgets 2027'!I$3:I$759,'[3]Budgets 2027'!Q$3:Q$759) -> CC046 | H83: =_xlfn.XLOOKUP(A83,'[3]Budgets 2027'!I$3:I$759,'[3]Budgets 2027'!R$3:R$759) -> Flat Trucks Logistics
A84: MVEH-000277 | B84: 0 | C84: Flat Trailer single Axel - 30T | D84: =_xlfn.XLOOKUP(A84,'[4]Fleet Master'!D$3:D$52,'[4]Fleet Master'!F$3:F$52) -> 35T | E84: 102-45T | F84: BOX BODY | G84: =_xlfn.XLOOKUP(A84,'[3]Budgets 2027'!I$3:I$759,'[3]Budgets 2027'!Q$3:Q$759) -> CC046 | H84: =_xlfn.XLOOKUP(A84,'[3]Budgets 2027'!I$3:I$759,'[3]Budgets 2027'!R$3:R$759) -> Flat Trucks Logistics
A85: MVEH-000290 | B85: 0 | C85: IPI FLAT TRAILER SINGLE AXEL-30T | D85: =_xlfn.XLOOKUP(A85,'[4]Fleet Master'!D$3:D$52,'[4]Fleet Master'!F$3:F$52) -> 30T | E85: FLAT | F85: Flat Trailer | G85: =_xlfn.XLOOKUP(A85,'[3]Budgets 2027'!I$3:I$759,'[3]Budgets 2027'!Q$3:Q$759) -> CC046 | H85: =_xlfn.XLOOKUP(A85,'[3]Budgets 2027'!I$3:I$759,'[3]Budgets 2027'!R$3:R$759) -> Flat Trucks Logistics
A86: MVEH-000302 | B86: 0 | C86: Flat Trailer single Axel - 30T | D86: 30T | E86: FLAT | F86: Flat Trailer | G86: =_xlfn.XLOOKUP(A86,'[3]Budgets 2027'!I$3:I$759,'[3]Budgets 2027'!Q$3:Q$759) -> CC046 | H86: =_xlfn.XLOOKUP(A86,'[3]Budgets 2027'!I$3:I$759,'[3]Budgets 2027'!R$3:R$759) -> Flat Trucks Logistics
A87: MVEH-000328 | B87: 0 | C87: Flat Body(15200x2650x2600 Tri AXLE | D87: =_xlfn.XLOOKUP(A87,'[4]Fleet Master'!D$3:D$52,'[4]Fleet Master'!F$3:F$52) -> 45T | E87: 102-45T | F87: BOX BODY | G87: =_xlfn.XLOOKUP(A87,'[3]Budgets 2027'!I$3:I$759,'[3]Budgets 2027'!Q$3:Q$759) -> CC059 | H87: =_xlfn.XLOOKUP(A87,'[3]Budgets 2027'!I$3:I$759,'[3]Budgets 2027'!R$3:R$759) -> Haulage
A88: MVEH-000330 | B88: 0 | C88: Flat Body(15200x2650x2600 Tri AXLE | D88: =_xlfn.XLOOKUP(A88,'[4]Fleet Master'!D$3:D$52,'[4]Fleet Master'!F$3:F$52) -> 30T | E88: SIDED-45T | F88: Sided | G88: =_xlfn.XLOOKUP(A88,'[3]Budgets 2027'!I$3:I$759,'[3]Budgets 2027'!Q$3:Q$759) -> CC059 | H88: =_xlfn.XLOOKUP(A88,'[3]Budgets 2027'!I$3:I$759,'[3]Budgets 2027'!R$3:R$759) -> Haulage
A89: MVEH-000332 | B89: 0 | C89: Flat Body(15200x2650x2600 Tri AXLE | D89: =_xlfn.XLOOKUP(A89,'[4]Fleet Master'!D$3:D$52,'[4]Fleet Master'!F$3:F$52) -> 30T | E89: 102-45T | F89: BOX BODY | G89: =_xlfn.XLOOKUP(A89,'[3]Budgets 2027'!I$3:I$759,'[3]Budgets 2027'!Q$3:Q$759) -> CC059 | H89: =_xlfn.XLOOKUP(A89,'[3]Budgets 2027'!I$3:I$759,'[3]Budgets 2027'!R$3:R$759) -> Haulage
A90: MVEH-000341 | B90: 0 | C90: Flat Body 12500x2500 Bogie Axle | D90: =_xlfn.XLOOKUP(A90,'[4]Fleet Master'!D$3:D$52,'[4]Fleet Master'!F$3:F$52) -> 45T | E90: 102-45T | F90: BOX BODY | G90: =_xlfn.XLOOKUP(A90,'[3]Budgets 2027'!I$3:I$759,'[3]Budgets 2027'!Q$3:Q$759) -> CC059 | H90: =_xlfn.XLOOKUP(A90,'[3]Budgets 2027'!I$3:I$759,'[3]Budgets 2027'!R$3:R$759) -> Haulage
A91: MVEH-000343 | B91: 0 | C91: Flat Body 12500x2500 Bogie Axle | D91: =_xlfn.XLOOKUP(A91,'[4]Fleet Master'!D$3:D$52,'[4]Fleet Master'!F$3:F$52) -> 30T | E91: FLAT | F91: Flat Trailer | G91: =_xlfn.XLOOKUP(A91,'[3]Budgets 2027'!I$3:I$759,'[3]Budgets 2027'!Q$3:Q$759) -> CC059 | H91: =_xlfn.XLOOKUP(A91,'[3]Budgets 2027'!I$3:I$759,'[3]Budgets 2027'!R$3:R$759) -> Haulage
A92: MVEH-000345 | B92: 0 | C92: Flat Body 12500x2500 Bogie Axle | D92: =_xlfn.XLOOKUP(A92,'[4]Fleet Master'!D$3:D$52,'[4]Fleet Master'!F$3:F$52) -> 45T | E92: 102-45T | F92: BOX BODY | G92: =_xlfn.XLOOKUP(A92,'[3]Budgets 2027'!I$3:I$759,'[3]Budgets 2027'!Q$3:Q$759) -> CC059 | H92: =_xlfn.XLOOKUP(A92,'[3]Budgets 2027'!I$3:I$759,'[3]Budgets 2027'!R$3:R$759) -> Haulage
A93: MVEH-000354 | B93: 0 | C93: JUMBO BOX BODY(15200 X 2650 X 2600)-TRI-AXLE, EPOXY PAINT | D93: =_xlfn.XLOOKUP(A93,'[4]Fleet Master'!D$3:D$52,'[4]Fleet Master'!F$3:F$52) -> 45T | E93: 102-45T | F93: BOX BODY | G93: =_xlfn.XLOOKUP(A93,'[3]Budgets 2027'!I$3:I$759,'[3]Budgets 2027'!Q$3:Q$759) -> CC059 | H93: =_xlfn.XLOOKUP(A93,'[3]Budgets 2027'!I$3:I$759,'[3]Budgets 2027'!R$3:R$759) -> Haulage
A94: MVEH-000355 | B94: 0 | C94: JUMBO BOX BODY(15200 X 2650 X 2600)-TRI-AXLE, EPOXY PAINT | D94: =_xlfn.XLOOKUP(A94,'[4]Fleet Master'!D$3:D$52,'[4]Fleet Master'!F$3:F$52) -> 45T | E94: 102-45T | F94: BOX BODY | G94: CC059 | H94: Haulage
...

Sheet Item List
A1: Item Number | B1: Vehicle Model | C1: Original Description | D1: Part Name | E1: Vehicle Type | F1: Make | G1: Original Category | H1: Category | I1: Group | J1: Subgroup | K1: Suggested Class | L1: Cost
A2: WS1460226 | B2: VOLKWAGEN | C2: Truck/VW/18310/Air Compressor | D2: Air Compressor | E2: Truck | F2: Volkswagen | G2: Mechanical | H2: Air Brake System | I2: Air Compressor | J2: Air Compressor Assembly | K2: Mechanical | L2: 320000
A3: WS1461310 | B3: — | C3: Truck/Foton/Hiab/Air Compressor | D3: Air Compressor | E3: Truck | F3: Foton | G3: Mechanical | H3: Air Brake System | I3: Air Compressor | J3: Air Compressor Assembly | K3: Mechanical | L3: 24000
A4: WS1460849 | B4: HOWO 371 6X4 DANGOTE | C4: Truck/Sino/6x4D/Air compressor assembly | D4: Air compressor assembly | E4: Truck | F4: Sinotruk HOWO | G4: Mechanical | H4: Air Brake System | I4: Air Compressor | J4: Air Compressor Assembly | K4: Mechanical | L4: 200000
A5: WS1460854 | B5: HOWO E7G371 6X4 (COVID) | C5: Truck/Sino/6x4C/AIR COMPRESSOR COVID19 | D5: AIR COMPRESSOR COVID19 | E5: Truck | F5: Sinotruk HOWO | G5: Mechanical | H5: Air Brake System | I5: Air Compressor | J5: Air Compressor Assembly | K5: Mechanical | L5: 240000
A6: WS1460219 | B6: HOWO E7G371 6X4 (COVID) | C6: Truck/Sino/All/Air Compressure Kit | D6: Air Compressure Kit | E6: Truck | F6: Sinotruk HOWO | G6: Mechanical | H6: Air Brake System | I6: Air Compressor | J6: Compressor Repair Kits & Gaskets | K6: Mechanical | L6: 0
A7: WS1460253 | B7: VOLKWAGEN | C7: Truck/VW/18310/Compressor Head Gasket | D7: Compressor Head Gasket | E7: Truck | F7: Volkswagen | G7: Mechanical | H7: Air Brake System | I7: Air Compressor | J7: Compressor Repair Kits & Gaskets | K7: Mechanical | L7: 18000
A8: SINO-6x4-COMPR-KIT | B8: HOWO E7G371 6X4 (COVID) | C8: Compressor kit | D8: Compressor kit | E8: Truck | F8: Sinotruk HOWO | G8: Mechanical | H8: Air Brake System | I8: Air Compressor | J8: Compressor Repair Kits & Gaskets | K8: Mechanical | L8: 0
A9: WS1460460 | B9: HOWO E7G371 6X4 (COVID) | C9: Truck/All/All/12Mm Air Hose Black | D9: 12Mm Air Hose Black | E9: Truck | F9: Universal | G9: Mechanical | H9: Air Brake System | I9: Air Lines & Fittings | J9: Air / Brake Hoses & Connectors | K9: Mechanical | L9: 1000
A10: WS1460288 | B10: VOLKWAGEN | C10: Truck/VW/18310/Air Coulper | D10: Air Coulper | E10: Truck | F10: Volkswagen | G10: Mechanical | H10: Air Brake System | I10: Air Lines & Fittings | J10: Air / Brake Hoses & Connectors | K10: Mechanical | L10: 0
A11: VW-18310-AIR-HOSE | B11: VOLKWAGEN | C11: Air hose | D11: Air hose | E11: Truck | F11: Volkswagen | G11: Mechanical | H11: Air Brake System | I11: Air Lines & Fittings | J11: Air / Brake Hoses & Connectors | K11: Mechanical | L11: 0
A12: WS1461202 | B12: HOWO E7G371 6X4 (COVID) | C12: All/All/All/Air Hose Quick Fix 12MM | D12: Air Hose Quick Fix 12MM | E12: All | F12: Universal | G12: Mechanical | H12: Air Brake System | I12: Air Lines & Fittings | J12: Air / Brake Hoses & Connectors | K12: Mechanical | L12: 1000
A13: WS1460461 | B13: HOWO E7G371 6X4 (COVID) | C13: All/All/All/Air Hose Quick Fix 6Mm | D13: Air Hose Quick Fix 6Mm | E13: All | F13: Universal | G13: Mechanical | H13: Air Brake System | I13: Air Lines & Fittings | J13: Air / Brake Hoses & Connectors | K13: Mechanical | L13: 1000
... A727: WS1460787 | B727: HOWO E7G371 6X4 (COVID) | C727: Truck/VW/18310/Threading Tape | D727: Threading Tape | E727: Truck | F727: Volkswagen | G727: Mechanical | H727: Workshop Consumables | I727: Tapes | J727: Thread Seal Tape | K727: Mechanical | L727: 300

Sheet Staffs List
A1: S/No | B1: Employee staff number | C1: NAME | D1: Position Name | E1: Company | F1: JOINING DATE | G1: Employee category | H1: Staff Group (Local/Expatriate/3rd Party | I1: Branch Code | J1: Branch Name | K1: costcenter | L1: CC Name | M1: Dept Code | N1: Dept Name | O1: Type | P1: Job Function | Q1: Division | R1: Business Unit | S1: Intercompany functions | T1: Within JMG function | U1: Reporting line Manager's Name | V1: Section | W1: Country of Resident
A2: 1 | B2: 000033 | C2: ADAH Joseph | D2: Bike Mechanic | E2: JMG | F2: 38341 | G2: Labour | H2: Local | I2: BRH002 | J2: Gbagada | K2: CC025 | L2: Vehicle Workshop | M2: DPT023 | N2: Vehicle Workshop | O2: Direct | P2: Logistics Support | Q2: Overhead | R2: Shared Services | S2: Dedicated Service | T2: Shared service | U2: GHASSAN El Saifi | V2: Vehicle Workshop | W2: Nigeria
A3: 2 | B3: 000083 | C3: ADESANYA Oluwatosin Oluwaseun | D3: HIAB Operator | E3: JMG | F3: 41191 | G3: Labour | H3: Local | I3: BRH002 | J3: Gbagada | K3: CC039 | L3: Hiabs Logistics | M3: DPT026 | N3: Logistics | O3: Direct | P3: Logistics | Q3: Logistics | R3: Transport | S3: Dedicated Service | T3: Dedicated service | U3: YEKEEN Oyetunde Bolarinwa | V3: Logistics | W3: Nigeria
A4: =A3+1 -> 3 | B4: 000089 | C4: ADEWUNMI Adetayo Joseph | D4: HIAB Operator | E4: JMG | F4: 42066 | G4: Labour | H4: Local | I4: BRH001 | J4: Abuja | K4: CC039 | L4: Hiabs Logistics | M4: DPT026 | N4: Logistics | O4: Direct | P4: Logistics | Q4: Logistics | R4: Transport | S4: Dedicated Service | T4: Dedicated service | U4: YEKEEN Oyetunde Bolarinwa | V4: Logistics | W4: Nigeria
A5: =A4+1 -> 4 | B5: 000105 | C5: AFOLABI Ayodeji | D5: HIAB Operator | E5: JMG | F5: 42887 | G5: Labour | H5: Local | I5: BRH002 | J5: Gbagada | K5: CC039 | L5: Hiabs Logistics | M5: DPT026 | N5: Logistics | O5: Direct | P5: Logistics | Q5: Logistics | R5: Transport | S5: Dedicated Service | T5: Dedicated service | U5: YEKEEN Oyetunde Bolarinwa | V5: Logistics | W5: Nigeria
A6: =A5+1 -> 5 | B6: 000133 | C6: AJIBADE Afeez Adeyemi | D6: Logistics Supervisor Heavy Duty | E6: JMG | F6: 41715 | G6: Admin | H6: Local | I6: BRH002 | J6: Gbagada | K6: CC024 | L6: Logistics And Transportation Ovh | M6: DPT026 | N6: Logistics | O6: Direct | P6: Logistics Support | Q6: Logistics | R6: Transport | S6: Dedicated Service | T6: Dedicated service | U6: DAYEKH Mohamad | V6: Logistics | W6: Nigeria
A7: =A6+1 -> 6 | B7: 000156 | C7: AKINDEJI Alfred Temidayo | D7: Light Duty Driver | E7: JMG | F7: 41438 | G7: Labour | H7: Local | I7: BRH002 | J7: Gbagada | K7: CC047 | L7: Closed Body Logistics | M7: DPT026 | N7: Logistics | O7: Direct | P7: Logistics | Q7: Logistics | R7: Transport | S7: Dedicated Service | T7: Dedicated service | U7: YEKEEN Oyetunde Bolarinwa | V7: Logistics | W7: Nigeria
A8: =A7+1 -> 7 | B8: 000163 | C8: AKINOLA Kehinde John | D8: Heavy Duty Driver | E8: JMG | F8: 41353 | G8: Labour | H8: Local | I8: BRH002 | J8: Gbagada | K8: CC059 | L8: HAULAGE | M8: DPT026 | N8: Logistics | O8: Direct | P8: Logistics | Q8: Logistics | R8: Transport | S8: Dedicated Service | T8: Dedicated service | U8: DAODU Timileyin Monday | V8: Logistics | W8: Nigeria
A9: =A8+1 -> 8 | B9: 000164 | C9: AKINOLA Oluwaseun Samson | D9: Heavy Duty Driver | E9: JMG | F9: 41344 | G9: Labour | H9: Local | I9: BRH002 | J9: Gbagada | K9: CC046 | L9: Flat Trucks Logistics | M9: DPT026 | N9: Logistics | O9: Direct | P9: Logistics | Q9: Logistics | R9: Transport | S9: Dedicated Service | T9: Dedicated service | U9: AJIBADE Afeez Adeyemi | V9: Logistics | W9: Nigeria
A10: =A9+1 -> 9 | B10: 000181 | C10: ALAMEZIE Denis Ndubuisi | D10: HIAB Operator | E10: JMG | F10: 42072 | G10: Labour | H10: Local | I10: BRH002 | J10: Gbagada | K10: CC039 | L10: Hiabs Logistics | M10: DPT026 | N10: Logistics | O10: Direct | P10: Logistics | Q10: Logistics | R10: Transport | S10: Dedicated Service | T10: Dedicated service | U10: YEKEEN Oyetunde Bolarinwa | V10: Logistics | W10: Nigeria
A11: =A10+1 -> 10 | B11: 000189 | C11: ALIYU Lawal | D11: Heavy Duty Driver | E11: JMG | F11: 42149 | G11: Labour | H11: Local | I11: BRH002 | J11: Gbagada | K11: CC059 | L11: HAULAGE | M11: DPT026 | N11: Logistics | O11: Direct | P11: Logistics | Q11: Logistics | R11: Transport | S11: Dedicated Service | T11: Dedicated service | U11: AJIBADE Afeez Adeyemi | V11: Logistics | W11: Nigeria
A12: =A11+1 -> 11 | B12: 000220 | C12: ASINI Ogwhonigho | D12: Logisitics Officer | E12: JMG | F12: 44830 | G12: Admin | H12: Local | I12: BRH009 | J12: PH | K12: CC066 | L12: Stores Operations | M12: DPT026 | N12: Logistics | O12: Indirect | P12: Logistics Support | Q12: Overhead | R12: Transport | S12: Dedicated Service | T12: Dedicated service | U12: DAYEKH Mohamad | V12: Logistics | W12: Nigeria
A13: =A12+1 -> 12 | B13: 000303 | C13: BANYE Franklin Asuamaka | D13: Trailer Motor Boy | E13: JMG | F13: 40882 | G13: Labour | H13: Local | I13: BRH002 | J13: Gbagada | K13: CC046 | L13: Flat Trucks Logistics | M13: DPT026 | N13: Logistics | O13: Direct | P13: Logistics | Q13: Logistics | R13: Transport | S13: Dedicated Service | T13: Dedicated service | U13: AJIBADE Afeez Adeyemi | V13: Logistics | W13: Nigeria
A14: =A13+1 -> 13 | B14: 000425 | C14: ESSIEN Micah Emmanuel | D14: Light Duty Driver | E14: JMG | F14: 40330 | G14: Labour | H14: Local | I14: BRH002 | J14: Gbagada | K14: CC047 | L14: Closed Body Logistics | M14: DPT026 | N14: Logistics | O14: Direct | P14: Logistics | Q14: Logistics | R14: Transport | S14: Dedicated Service | T14: Dedicated service | U14: YEKEEN Oyetunde Bolarinwa | V14: Logistics | W14: Nigeria
A15: =A14+1 -> 14 | B15: 000450 | C15: EZRA Mallam | D15: HIAB Operator | E15: JMG | F15: 42887 | G15: Labour | H15: Local | I15: BRH001 | J15: Abuja | K15: CC024 | L15: Logistics And Transportation Ovh | M15: DPT026 | N15: Logistics | O15: Direct | P15: Logistics | Q15: Logistics | R15: Transport | S15: Dedicated Service | T15: Dedicated service | U15: YEKEEN Oyetunde Bolarinwa | V15: Logistics | W15: Nigeria
... A132: =A131+1 -> 131 | B132: 003119 | C132: OGUNLEYE Abiodun Amos | D132: Auto Electrician | E132: JMG | F132: 45432 | G132: Labour | H132: Local | I132: BRH002 | J132: Gbagada | K132: CC024 | L132: Logistics And Transportation Ovh | M132: DPT023 | N132: Vehicle Workshop | O132: Direct | P132: Logistics Support | Q132: Overhead | R132: Transport | S132: Dedicated Service | T132: Shared service | U132: ADEGOKE Ademola Abdulkareem | V132: Vehicle Workshop | W132: Nigeria

Sheet Supplier
F2: Scope | G2: Equipment Providor | H2: Equipment Providor | I2: Equipment Providor | J2: Equipment Providor | K2: Equipment Providor | L2: Equipment Providor | M2: Equipment Providor | N2: Travels Upcountry | O2: Delivery Local within State | P2: Equipment Providor | Q2: Sell Equiment | R2: Sell Equiment | S2: Spare Parts | T2: External Workshop | U2: Tracking Company | V2: Diesel Supplier | W2: Tyre Supplier
F3: Expenses Type | G3: Opex | H3: Opex | I3: Opex | J3: Opex | K3: Opex | L3: Opex | M3: Opex | N3: Operation Type | O3: Operation Type | P3: Opex | Q3: Capex | R3: Capex | S3: Opex | T3: Opex | U3: Opex | V3: Opx | W3: Opex
A4: Supplier account | B4: Name | C4: Supplier hold | D4: Proposed | E4: Type Of Expenses | F4: Used by Division | G4: HAIB | H4: Crane | I4: FLATBED | J4: Low-bed | K4: 20FT | L4: 25FT | M4: 40FT | N4: Upcountry | O4: Local | P4: Forklift | Q4: Trucks | R4: Trailers | S4: Spare Parts | T4: External Workshop | U4: Tracking Company | V4: Diesel Supplier | W4: Tyre Supplier
A5: V00001019 | B5: IRON PRODUCTS INDUSTRIES LTD | C5: No | D5: 30D | E5: Non Stock | F5: Transport Division | G5: NO | H5: NO | I5: NO | J5: NO | K5: NO | L5: NO | M5: NO | N5: NO | O5: NO | P5: NO | Q5: Yes | R5: Yes | S5: Yes | T5: Yes | U5: NO | V5: NO | W5: NO
A6: V00001429 | B6: ONE STOP AFRICA INDUSTRIES LIMITED | C6: No | D6: 30D | E6: Stock Item | F6: Vehicle Workshop | G6: NO | H6: NO | I6: NO | J6: NO | K6: NO | L6: NO | M6: NO | N6: NO | O6: NO | P6: NO | Q6: NO | R6: NO | S6: Yes | T6: Yes | U6: NO | V6: NO | W6: NO
A7: V00001514 | B7: C.WOERMANN(NIGERIA)LIMITED | C7: No | D7: 30D | E7: Stock Item | F7: Vehicle Workshop | G7: NO | H7: NO | I7: NO | J7: NO | K7: NO | L7: NO | M7: NO | N7: NO | O7: NO | P7: NO | Q7: NO | R7: NO | S7: Yes | T7: NO | U7: NO | V7: NO | W7: NO
A8: V00000042 | B8: HAYYLUCK NIG LTD | C8: No | D8: Payment on Invoice | E8: Non Stock | F8: 3rd party Logistics | G8: YES | H8: YES | I8: YES | J8: YES | K8: NO | L8: NO | M8: NO | N8: YES | O8: YES | P8: YES | Q8: NO | R8: NO | S8: NO | T8: Yes | U8: NO | V8: NO | W8: NO
A9: V00001279 | B9: QT CONCEPTS LTD | C9: No | D9: 30D | E9: Stock Item | F9: Vehicle Workshop | G9: NO | H9: NO | I9: NO | J9: NO | K9: NO | L9: NO | M9: NO | N9: NO | O9: NO | P9: NO | Q9: NO | R9: NO | S9: Yes | T9: NO | U9: NO | V9: NO | W9: NO
A10: V00000699 | B10: PAT-ELLENZ INTERNATIONAL NIG. | C10: No | D10: Payment on Invoice | E10: Non Stock | F10: 3rd party Logistics | G10: YES | H10: YES | I10: YES | J10: YES | K10: YES | L10: YES | M10: YES | N10: YES | O10: YES | P10: YES | Q10: NO | R10: NO | S10: NO | T10: Yes | U10: NO | V10: NO | W10: NO
A11: V00001297 | B11: MAM IMPEX CONCEPT LTD | C11: No | D11: 30D | E11: Stock Item | F11: Vehicle Workshop | G11: NO | H11: NO | I11: NO | J11: NO | K11: NO | L11: NO | M11: NO | N11: NO | O11: NO | P11: NO | Q11: NO | R11: NO | S11: Yes | T11: NO | U11: NO | V11: NO | W11: NO
A12: V00000802 | B12: OMOS AND SONS NIGERIA LIMITED | C12: No | D12: Payment on Invoice | E12: Non Stock | F12: 3rd party Logistics | G12: YES | H12: YES | I12: YES | J12: YES | K12: YES | L12: YES | M12: YES | N12: YES | O12: YES | P12: YES | Q12: NO | R12: NO | S12: NO | T12: Yes | U12: NO | V12: NO | W12: NO
A13: V00000185 | B13: CHRISTMAN AUTO. SUPPLY | C13: No | D13: 30D | E13: Stock Item | F13: Vehicle Workshop | G13: NO | H13: NO | I13: NO | J13: NO | K13: NO | L13: NO | M13: NO | N13: NO | O13: NO | P13: NO | Q13: NO | R13: NO | S13: Yes | T13: NO | U13: NO | V13: NO | W13: NO
A14: V00001231 | B14: ANIBIRE ANIS & SONS NIGERIA ENTERPRIES | C14: No | D14: Payment on Invoice | E14: Non Stock | F14: 3rd party Logistics | G14: YES | H14: YES | I14: YES | J14: NO | K14: NO | L14: NO | M14: NO | N14: NO | O14: NO | P14: NO | Q14: NO | R14: NO | S14: NO | T14: NO | U14: NO | V14: NO | W14: NO
A15: V00000941 | B15: MOJEED OSUOLALE ENTERPRISES | C15: No | D15: 30D | E15: Stock Item | F15: Vehicle Workshop | G15: NO | H15: NO | I15: NO | J15: NO | K15: NO | L15: NO | M15: NO | N15: NO | O15: NO | P15: NO | Q15: NO | R15: NO | S15: Yes | T15: NO | U15: NO | V15: NO | W15: NO
... A59: V00000328 | B59: OPTIMAS OE SOLUTIONS LTD | C59: No | D59: 30D | E59: Stock Item | F59: Diesel | G59: NO | H59: NO | I59: NO | J59: NO | K59: NO | L59: NO | M59: NO | N59: NO | O59: NO | P59: NO | Q59: NO | R59: NO | S59: NO | T59: NO | U59: NO | V59: YES | W59: NO

Sheet LOB
B2: Haulage
B3: Port Operations
B4: Hiab
B5: Vans
B6: Crane & Heavy Lifts
B7: 3PL

Sheet Rate Card for costing 
A2: DIVISION | B2: OLD PLATE NO | C2: NEW PLATE NO | D2: ASSET ID | E2: Consumption | F2: Mentaiance Budget | G2: Montly Trip | H2: KM | I2: Project Number of Day | J2: Planned | K2: Actual Fixed Cost | L2: MTC Cost Per KM | M2: Tyre Cost Per KM | N2: Road Expenses Per KM | O2: Selling Fixed
A3: Closed Body Logistics | B3: AAA822XS | C3: AAA822XS | D3: MVEH-000202 | E3: 0.15 | F3: 7800 | G3: 16 | H3: 650 | I3: 236 | J3: 236 | K3: 57798.9 | L3: 83.333333 | M3: 2.7692308 | N3: 38 | O3: 75138.57
A4: Closed Body Logistics | B4: KSF352YC | C4: KSF352YC | D4: MVEH-000304 | E4: 0.2 | F4: 7800 | G4: 16 | H4: 650 | I4: 236 | J4: 236 | K4: 42975.81 | L4: 55.128205 | M4: 4.6153846 | N4: 38 | O4: 55868.553
A5: Closed Body Logistics | B5: T-1589LA | C5: T-1589LA | D5: MVEH-000289 | E5: 0.25 | F5: 12000 | G5: 16 | H5: 1000 | I5: 236 | J5: 236 | K5: 53846.91 | L5: 66.666667 | M5: 13.846154 | N5: 49 | O5: 70000.983
A6: Closed Body Logistics | B6: T-1590LA | C6: T-1590LA | D6: MVEH-000288 | E6: 0.25 | F6: 12000 | G6: 16 | H6: 1000 | I6: 236 | J6: 236 | K6: 51668.075 | L6: 66.666667 | M6: 13.846154 | N6: 49 | O6: 67168.497
A7: Closed Body Logistics | B7: T-1678LA | C7: T-1678LA | D7: MVEH-000287 | E7: 0.25 | F7: 12000 | G7: 16 | H7: 1000 | I7: 236 | J7: 236 | K7: 51744.759 | L7: 66.666667 | M7: 13.846154 | N7: 49 | O7: 67268.186
A8: Closed Body Logistics | B8: GGE28XU | C8: KRD640YF | D8: MVEH-000363 | E8: 0.25 | F8: 12000 | G8: 16 | H8: 1000 | I8: 236 | J8: 236 | K8: 54975.303 | L8: 66.666667 | M8: 13.846154 | N8: 49 | O8: 71467.893
A9: Closed Body Logistics | B9: KTU69XP | C9: T-2413LA | D9: MVEH-000146 | E9: 0.35 | F9: 21600 | G9: 16 | H9: 1800 | I9: 236 | J9: 236 | K9: 82650.804 | L9: 94.907407 | M9: 23.076923 | N9: 59 | O9: 107446.05
A10: Closed Body Logistics | B10: KTU68XP | C10: T-2417LA | D10: MVEH-000145 | E10: 0.35 | F10: 21600 | G10: 16 | H10: 1800 | I10: 236 | J10: 236 | K10: 86200.454 | L10: 94.907407 | M10: 23.076923 | N10: 59 | O10: 112060.59
A11: Hiabs Logistics | B11: KTU74XP | C11: KTU74XP | D11: MVEH-000103 | E11: 0.42 | F11: 21600 | G11: 16 | H11: 1800 | I11: 284 | J11: 284 | K11: 98036.085 | L11: 145.83333 | M11: 24.615385 | N11: 80 | O11: 127446.91
A12: Hiabs Logistics | B12: KTU76XP | C12: KTU76XP | D12: MVEH-000101 | E12: 0.42 | F12: 21600 | G12: 16 | H12: 1800 | I12: 284 | J12: 284 | K12: 96572.173 | L12: 145.83333 | M12: 24.615385 | N12: 80 | O12: 125543.82
A13: Hiabs Logistics | B13: KTU77XP | C13: KTU77XP | D13: MVEH-000102 | E13: 0.42 | F13: 21600 | G13: 16 | H13: 1800 | I13: 284 | J13: 284 | K13: 89136.641 | L13: 145.83333 | M13: 30.769231 | N13: 80 | O13: 115877.63
A14: Hiabs Logistics | B14: KTU79XP | C14: T-2405LA | D14: MVEH-000105 | E14: 0.42 | F14: 21600 | G14: 16 | H14: 1800 | I14: 284 | J14: 284 | K14: 94395.326 | L14: 145.83333 | M14: 24.615385 | N14: 80 | O14: 122713.92
... A42: HAULAGE | B42: T20358LA | C42: T20358LA | D42: MVEH-000334 | E42: 0.5 | F42: 66000 | G42: 3 | H42: 5500 | I42: 260 | J42: 260 | K42: 145036.61 | L42: 81.439394 | M42: 143.84615 | N42: 25 | O42: 210303.08
A43: NBL-DSL | B43: =_xlfn.XLOOKUP(D43,'Asset Code'!$A:$A,'Asset Code'!$B:$B) -> T33405LA | C43: =B43 -> T33405LA | D43: MVEH-000443 | E43: 0.5 | F43: 66000 | G43: 3 | H43: 5500 | I43: 293 | J43: 293 | K43: 187900.17 | L43: 99.621212 | M43: 143.84615 | N43: 36 | O43: 244270.22
A44: NBL-DSL | B44: =_xlfn.XLOOKUP(D44,'Asset Code'!$A:$A,'Asset Code'!$B:$B) -> T33404LA | C44: =B44 -> T33404LA | D44: MVEH-000444 | E44: 0.5 | F44: 66000 | G44: 3 | H44: 5500 | I44: 293 | J44: 293 | K44: 187900.17 | L44: 99.621212 | M44: 143.84615 | N44: 36 | O44: 244270.22
A45: NBL-DSL | B45: =_xlfn.XLOOKUP(D45,'Asset Code'!$A:$A,'Asset Code'!$B:$B) -> T33403LA | C45: =B45 -> T33403LA | D45: MVEH-000445 | E45: 0.5 | F45: 66000 | G45: 3 | H45: 5500 | I45: 293 | J45: 293 | K45: 187900.17 | L45: 99.621212 | M45: 143.84615 | N45: 36 | O45: 244270.22
A46: NBL-DSL | B46: =_xlfn.XLOOKUP(D46,'Asset Code'!$A:$A,'Asset Code'!$B:$B) -> T33402LA | C46: =B46 -> T33402LA | D46: MVEH-000446 | E46: 0.5 | F46: 66000 | G46: 3 | H46: 5500 | I46: 293 | J46: 293 | K46: 187900.17 | L46: 99.621212 | M46: 143.84615 | N46: 36 | O46: 244270.22
A47: NBL-DSL | B47: =_xlfn.XLOOKUP(D47,'Asset Code'!$A:$A,'Asset Code'!$B:$B) -> T33401LA | C47: =B47 -> T33401LA | D47: MVEH-000447 | E47: 0.5 | F47: 66000 | G47: 3 | H47: 5500 | I47: 293 | J47: 293 | K47: 187900.17 | L47: 99.621212 | M47: 143.84615 | N47: 36 | O47: 244270.22
A48: NBL-DSL | B48: =_xlfn.XLOOKUP(D48,'Asset Code'!$A:$A,'Asset Code'!$B:$B) -> T33213LA | C48: =B48 -> T33213LA | D48: MVEH-000448 | E48: 0.5 | F48: 66000 | G48: 3 | H48: 5500 | I48: 293 | J48: 293 | K48: 187900.17 | L48: 99.621212 | M48: 143.84615 | N48: 36 | O48: 244270.22
A49: NBL-DSL | B49: =_xlfn.XLOOKUP(D49,'Asset Code'!$A:$A,'Asset Code'!$B:$B) -> T33076LA | C49: =B49 -> T33076LA | D49: MVEH-000449 | E49: 0.5 | F49: 66000 | G49: 3 | H49: 5500 | I49: 293 | J49: 293 | K49: 187900.17 | L49: 99.621212 | M49: 143.84615 | N49: 36 | O49: 244270.22
A50: NBL-DSL | B50: =_xlfn.XLOOKUP(D50,'Asset Code'!$A:$A,'Asset Code'!$B:$B) -> T33075LA | C50: =B50 -> T33075LA | D50: MVEH-000450 | E50: 0.5 | F50: 66000 | G50: 3 | H50: 5500 | I50: 293 | J50: 293 | K50: 187900.17 | L50: 99.621212 | M50: 143.84615 | N50: 36 | O50: 244270.22
A51: NBL-DSL | B51: =_xlfn.XLOOKUP(D51,'Asset Code'!$A:$A,'Asset Code'!$B:$B) -> T33074LA | C51: =B51 -> T33074LA | D51: MVEH-000451 | E51: 0.5 | F51: 66000 | G51: 3 | H51: 5500 | I51: 293 | J51: 293 | K51: 187900.17 | L51: 99.621212 | M51: 143.84615 | N51: 36 | O51: 244270.22
A52: NBL-DSL | B52: =_xlfn.XLOOKUP(D52,'Asset Code'!$A:$A,'Asset Code'!$B:$B) -> T33073LA | C52: =B52 -> T33073LA | D52: MVEH-000452 | E52: 0.5 | F52: 66000 | G52: 3 | H52: 5500 | I52: 293 | J52: 293 | K52: 187900.17 | L52: 99.621212 | M52: 143.84615 | N52: 36 | O52: 244270.22
A53: NBL-CNG | B53: NBL11 | C53: NBL11 | D53: MVEH-000433 | E53: 0.7 | F53: 66000 | G53: 3 | H53: 5500 | I53: 293 | J53: 293 | K53: 204282.42 | L53: 99.621212 | M53: 143.84615 | N53: 36 | O53: 265567.15
A54: NBL-CNG | B54: NBL12 | C54: NBL12 | D54: MVEH-000434 | E54: 0.7 | F54: 66000 | G54: 3 | H54: 5500 | I54: 293 | J54: 293 | K54: 204282.42 | L54: 99.621212 | M54: 143.84615 | N54: 36 | O54: 265567.15
A55: NBL-CNG | B55: NBL13 | C55: NBL13 | D55: MVEH-000435 | E55: 0.7 | F55: 66000 | G55: 3 | H55: 5500 | I55: 293 | J55: 293 | K55: 204282.42 | L55: 99.621212 | M55: 143.84615 | N55: 36 | O55: 265567.15
A56: NBL-CNG | B56: NBL14 | C56: NBL14 | D56: MVEH-000436 | E56: 0.7 | F56: 66000 | G56: 3 | H56: 5500 | I56: 293 | J56: 293 | K56: 204282.42 | L56: 99.621212 | M56: 143.84615 | N56: 36 | O56: 265567.15
A57: NBL-CNG | B57: NBL15 | C57: NBL15 | D57: MVEH-000437 | E57: 0.7 | F57: 66000 | G57: 3 | H57: 5500 | I57: 293 | J57: 293 | K57: 204282.42 | L57: 99.621212 | M57: 143.84615 | N57: 36 | O57: 265567.15
A58: NBL-CNG | B58: NBL16 | C58: NBL16 | D58: MVEH-000438 | E58: 0.7 | F58: 66000 | G58: 3 | H58: 5500 | I58: 293 | J58: 293 | K58: 204282.42 | L58: 99.621212 | M58: 143.84615 | N58: 36 | O58: 265567.15
A59: NBL-CNG | B59: NBL17 | C59: NBL17 | D59: MVEH-000439 | E59: 0.7 | F59: 66000 | G59: 3 | H59: 5500 | I59: 293 | J59: 293 | K59: 204282.42 | L59: 99.621212 | M59: 143.84615 | N59: 36 | O59: 265567.15
A60: NBL-CNG | B60: NBL18 | C60: NBL18 | D60: MVEH-000440 | E60: 0.7 | F60: 66000 | G60: 3 | H60: 5500 | I60: 293 | J60: 293 | K60: 204282.42 | L60: 99.621212 | M60: 143.84615 | N60: 36 | O60: 265567.15
A61: NBL-CNG | B61: NBL19 | C61: NBL19 | D61: MVEH-000441 | E61: 0.7 | F61: 66000 | G61: 3 | H61: 5500 | I61: 293 | J61: 293 | K61: 204282.42 | L61: 99.621212 | M61: 143.84615 | N61: 36 | O61: 265567.15
A62: NBL-CNG | B62: NBL20 | C62: NBL20 | D62: MVEH-000442 | E62: 0.7 | F62: 66000 | G62: 3 | H62: 5500 | I62: 293 | J62: 293 | K62: 204282.42 | L62: 99.621212 | M62: 143.84615 | N62: 36 | O62: 265567.15
A63: Flat Trucks Logistics- | B63: KJA44XZ | C63: T-2404LA | D63: MVEH-000266 | E63: 0.42 | F63: 11700 | G63: 6.5 | H63: 975 | I63: 260 | J63: 260 | K63: 113224.05 | L63: 382.47863 | M63: 53.846154 | N63: 25 | O63: 271737.72
A64: Flat Trucks Logistics- | B64: LSD698XZ | C64: T-2407LA | D64: MVEH-000271 | E64: 0.42 | F64: 11700 | G64: 6.5 | H64: 975 | I64: 260 | J64: 260 | K64: 114569.74 | L64: 382.47863 | M64: 53.846154 | N64: 25 | O64: 274967.36
... A69: Flat Trucks Logistics- | B69: KJA47XZ | C69: T-2490LA | D69: MVEH-000269 | E69: 0.42 | F69: 11700 | G69: 6.5 | H69: 975 | I69: 260 | J69: 260 | K69: 113614.43 | L69: 382.47863 | M69: 53.846154 | N69: 25 | O69: 272674.64

Sheet KPI
A2: KPI
A3: Driving KM Per Day for All Upcountry trucks | B3: 300KM
A4: Offloading and offloading for all deliveries should be 1 day | B4: 1 Day
A5: Diesel Hiab | B5: 0.42
A6: Flat Bed Diesel needed | B6: 0.42
A7: Haulage truck 30T -102 | B7: 0.42
A8: Haulage Truck 45T 102 | B8: 0.5
A9: CNG Truck consumption | B9: 0.75
A10: 16CBM Truck | B10: 0.15
A11: 30CBM Truck | B11: 0.35
A15: Logistics Port Expenses | B15: Driver Road Expenses | C15: Additional Diesel | D15: Passing Truck Express | E15: Dropping Empty
A16: APMT-MSC | B16: 114000 | C16: 40000 | D16: 300000 | E16: 80000
A17: APMT-CMA | B17: 114000 | C17: 40000 | D17: 300000 | E17: 39000
A18: ESS-Libra-CMA | B18: 114000 | C18: 40000 | D18: 40000 | E18: 39000
A19: ESS-Libra-MSC | B19: 114000 | C19: 40000 | D19: 40000 | E19: 80000
A20: Ikorudo-CMA | B20: 114000 | C20: 40000 | D20: 40000 | E20: 39000
A21: Ikorudo-MSC | B21: 114000 | C21: 40000 | D21: 40000 | E21: 80000

Sheet Expense Account 
A1: Type | B1: Account number | C1: Account Name | D1: Expense Type | E1: KPI
A2: Operational Expenses | B2: 6101027 | C2: Logistics Allowances | D2: Drivers Trip Expenses | E2: 25 Naira Per KM
B3: 6103008 | C3: Diesel for Hiabs | D3: Diesel from Internal Fuel Dump | E3: Use KPI Sheet
B4: 6103009 | C4: Diesel for Lorries | D4: Diesel from Internal Fuel Dump | E4: Use KPI Sheet
B5: 6103013 | C5: Fuel and Diesel Logistics Allowances | D5: Cash Allowance to buy Diesel | E5: Additional Expense on Created Trip
B6: New Account | C6: CNG Expense | D6: Cash Allowance for CNG | E6: Use KPI Sheet
B7: 6105047 | C7: Logistics Misc Expenses | D7: Tickets and Sticker Payments | E7: Additional Expense on Created Trip
B8: 6105051 | C8: Logistics Port Expenses | D8: Port Operation Expenses | E8: Use KPI Sheet
B9: 6102028 | C9: Truck Tyre Expenses | D9: Tyre Expenses | E9: MTC Module
B10: 6102010 | C10: Lorries Maintenance Expenses | D10: Tractor and Trailer Repairs | E10: MTC Module
B11: 6102009 | C11: Hiabs Maintenance Expenses | D11: Hiab | E11: MTC Module
B12: 6101030 | C12: Logistics Positioning-Pushing Allowances | D12: Manual Pushing | E12: Additional Expense on Created Trip
B13: 6105061 | C13: Delivery Allowance Misc | D13: Community Settlement | E13: Additional Expense on Created Trip
B14: 6105040 | C14: Towing/Other Vehicle Breakdown Expenses | D14: Towing | E14: Expense Module Request
B15: 6105001 | C15: Transportation And Offloading Of Finished Goods | D15: 3rd Party contracted Trucks | E15: 3PL PO
B16: 6105002 | C16: Crane & Heavy Lifts | D16: Crane & Heavy Lifts | E16: 3PL PO
B17: 6105003 | C17: Staff Transportation | D17: Transport for Operational Staffs | E17: 3PL PO
B18: New Account | C18: Tracking System | D18: For subscription of Tracking | E18: PO Level should all be posted on the asset
A19: Non-Operational Expenses | C19: Insurance | D19: Vehicle Insurance | E19: Entries on Asset
C20: GIT | D20: Good in Transit
C21: License and Permit | D21: License and Permit | E21: Entries on Asset
C22: Salaries Local and Expat
C23: Rent | D23: House rents offices and Yard
C24: Depreciation | D24: Vehicle Depreciation

Sheet All Routes
A1: Contract Name | B1: Truck Size | C1: Division | D1: Truck Tonnage | E1: Client | F1: Client Main Location | G1: Loading Point | H1: Loading State | I1: Destination (corrected) | J1: Destination State | K1: Region (geopolitical zone) | L1: Delivery Type | M1: Internal Zone | N1: Stops (in drive order) | O1: Leg Breakdown (km) | P1: Leg 1 - Outbound KM | Q1: Leg 2 - Return KM | R1: Total Round Trip KM | S1: KM Source | T1: Notes
A2: JAT-45T-NBL-DSL-JUMBO | B2: JUMBO | C2: NBL-DSL | D2: 45T | E2: JAT | F2: Ibadan | G2: Ibadan | H2: Oyo | I2: Kano | J2: Kano | K2: North West | L2: Interstate | N2: Kano | O2: Ibadan > Kano: 876 | Return Kano > Ibadan: 876 | P2: 876 | Q2: 876 | R2: =IF(P2="","",P2+Q2) -> 1752 | S2: Estimated (calibrated)
A3: ABBA SALEH-45T-NBL-DSL-JUMBO | B3: JUMBO | C3: NBL-DSL | D3: 45T | E3: ABBA SALEH | F3: Keffi | G3: Keffi | H3: Nasarawa | I3: Ogere | J3: Ogun | K3: South West | L3: Interstate | N3: Ogere | O3: Keffi > Ogere: 728 | Return Ogere > Keffi: 728 | P3: 728 | Q3: 728 | R3: =IF(P3="","",P3+Q3) -> 1456 | S3: Road-routed (OpenStreetMap)
A4: ABBA SALEH-30T-NBL-DSL-JUMBO | B4: JUMBO | C4: NBL-DSL | D4: 30T | E4: ABBA SALEH | F4: Keffi | G4: Keffi | H4: Nasarawa | I4: Ogere | J4: Ogun | K4: South West | L4: Interstate | N4: Ogere | O4: Keffi > Ogere: 728 | Return Ogere > Keffi: 728 | P4: 728 | Q4: 728 | R4: =IF(P4="","",P4+Q4) -> 1456 | S4: Road-routed (OpenStreetMap)
A5: JAT-45T-NBL-DSL-JUMBO | B5: JUMBO | C5: NBL-DSL | D5: 45T | E5: JAT | F5: Ibadan | G5: Ibadan | H5: Oyo | I5: Abuja | J5: FCT | K5: North Central | L5: Interstate | N5: Abuja | O5: Ibadan > Abuja: 612 | Return Abuja > Ibadan: 612 | P5: 612 | Q5: 612 | R5: =IF(P5="","",P5+Q5) -> 1224 | S5: Estimated (calibrated)
A6: JAT-45T-NBL-DSL-JUMBO | B6: JUMBO | C6: NBL-DSL | D6: 45T | E6: JAT | F6: Ibadan | G6: Ibadan | H6: Oyo | I6: Suleja | J6: Niger | K6: North Central | L6: Interstate | N6: Suleja | O6: Ibadan > Suleja: 578 | Return Suleja > Ibadan: 578 | P6: 578 | Q6: 578 | R6: =IF(P6="","",P6+Q6) -> 1156 | S6: Estimated (calibrated)
A7: JAT-45T-NBL-DSL-JUMBO | B7: JUMBO | C7: NBL-DSL | D7: 45T | E7: JAT | F7: Ibadan | G7: Ibadan | H7: Oyo | I7: Sokoto | J7: Sokoto | K7: North West | L7: Interstate | N7: Sokoto | O7: Ibadan > Sokoto: 787 | Return Sokoto > Ibadan: 787 | P7: 787 | Q7: 787 | R7: =IF(P7="","",P7+Q7) -> 1574 | S7: Estimated (calibrated)
A8: JAT-45T-NBL-DSL-JUMBO | B8: JUMBO | C8: NBL-DSL | D8: 45T | E8: JAT | F8: Ibadan | G8: Ibadan | H8: Oyo | I8: Wukari | J8: Taraba | K8: North East | L8: Interstate | N8: Wukari | O8: Ibadan > Wukari: 846 | Return Wukari > Ibadan: 846 | P8: 846 | Q8: 846 | R8: =IF(P8="","",P8+Q8) -> 1692 | S8: Estimated (calibrated)
A9: JAT-45T-NBL-DSL-JUMBO | B9: JUMBO | C9: NBL-DSL | D9: 45T | E9: JAT | F9: Ibadan | G9: Ibadan | H9: Oyo | I9: Jalingo | J9: Taraba | K9: North East | L9: Interstate | N9: Jalingo | O9: Ibadan > Jalingo: 1090 | Return Jalingo > Ibadan: 1090 | P9: 1090 | Q9: 1090 | R9: =IF(P9="","",P9+Q9) -> 2180 | S9: Estimated (calibrated)
A10: JAT-45T-NBL-DSL-JUMBO | B10: JUMBO | C10: NBL-DSL | D10: 45T | E10: JAT | F10: Ibadan | G10: Ibadan | H10: Oyo | I10: Kontagora | J10: Niger | K10: North Central | L10: Interstate | N10: Kontagora | O10: Ibadan > Kontagora: 527 | Return Kontagora > Ibadan: 527 | P10: 527 | Q10: 527 | R10: =IF(P10="","",P10+Q10) -> 1054 | S10: Estimated (calibrated)
A11: JAT-45T-NBL-DSL-JUMBO | B11: JUMBO | C11: NBL-DSL | D11: 45T | E11: JAT | F11: Ibadan | G11: Ibadan | H11: Oyo | I11: Gombe | J11: Gombe | K11: North East | L11: Interstate | N11: Gombe | O11: Ibadan > Gombe: 1120 | Return Gombe > Ibadan: 1120 | P11: 1120 | Q11: 1120 | R11: =IF(P11="","",P11+Q11) -> 2240 | S11: Estimated (calibrated)
A12: JAT-45T-NBL-DSL-JUMBO | B12: JUMBO | C12: NBL-DSL | D12: 45T | E12: JAT | F12: Ibadan | G12: Ibadan | H12: Oyo | I12: Minna | J12: Niger | K12: North Central | L12: Interstate | N12: Minna | O12: Ibadan > Minna: 535 | Return Minna > Ibadan: 535 | P12: 535 | Q12: 535 | R12: =IF(P12="","",P12+Q12) -> 1070 | S12: Estimated (calibrated)
A13: JAT-45T-NBL-DSL-JUMBO | B13: JUMBO | C13: NBL-DSL | D13: 45T | E13: JAT | F13: Ibadan | G13: Ibadan | H13: Oyo | I13: Zaria | J13: Kaduna | K13: North West | L13: Interstate | N13: Zaria | O13: Ibadan > Zaria: 713 | Return Zaria > Ibadan: 713 | P13: 713 | Q13: 713 | R13: =IF(P13="","",P13+Q13) -> 1426 | S13: Estimated (calibrated)
... A39: JAT-45T-NBL-DSL-JUMBO | B39: JUMBO | C39: NBL-DSL | D39: 45T | E39: JAT | F39: Ibadan | G39: Ibadan | H39: Oyo | I39: Koko (Kebbi) | J39: Kebbi | K39: North West | L39: Interstate | N39: Koko | O39: Ibadan > Koko: 553 | Return Koko > Ibadan: 553 | P39: 553 | Q39: 553 | R39: =IF(P39="","",P39+Q39) -> 1106 | S39: Estimated (calibrated)
A40: JAT-45T-NBL-DSL-JUMBO | B40: JUMBO | C40: NBL-DSL | D40: 45T | E40: JAT | F40: Ibadan | G40: Ibadan | H40: Oyo | I40: Ibadan | J40: Oyo | K40: South West | L40: Internal (within state) | M40: Outside listed zones | N40: Ibadan | O40: Ibadan > Ibadan: 10 | Return Ibadan > Ibadan: 10 | P40: 10 | Q40: 10 | R40: =IF(P40="","",P40+Q40) -> 20 | S40: Estimated (calibrated) | T40: Delivery inside the loading town - 10 km allowance each way
A41: JAT-45T-NBL-DSL-JUMBO | B41: JUMBO | C41: NBL-DSL | D41: 45T | E41: JAT | F41: Ibadan | G41: Ibadan | H41: Oyo | I41: Ekpoma | J41: Edo | K41: South South | L41: Interstate | N41: Ekpoma | O41: Ibadan > Ekpoma: 315 | Return Ekpoma > Ibadan: 315 | P41: 315 | Q41: 315 | R41: =IF(P41="","",P41+Q41) -> 630 | S41: Estimated (calibrated)
A42: JAT-45T-NBL-DSL-JUMBO | B42: JUMBO | C42: NBL-DSL | D42: 45T | E42: JAT | F42: Ibadan | G42: Ibadan | H42: Oyo | I42: Aba | J42: Abia | K42: South East | L42: Interstate | N42: Aba | O42: Ibadan > Aba: 580 | Return Aba > Ibadan: 580 | P42: 580 | Q42: 580 | R42: =IF(P42="","",P42+Q42) -> 1160 | S42: Estimated (calibrated)
A43: JAT-45T-NBL-DSL-JUMBO | B43: JUMBO | C43: NBL-DSL | D43: 45T | E43: JAT | F43: Ibadan | G43: Ibadan | H43: Oyo | I43: Agbor | J43: Delta | K43: South South | L43: Interstate | N43: Agbor | O43: Ibadan > Agbor: 357 | Return Agbor > Ibadan: 357 | P43: 357 | Q43: 357 | R43: =IF(P43="","",P43+Q43) -> 714 | S43: Estimated (calibrated)
A44: JAT-45T-NBL-DSL-JUMBO | B44: JUMBO | C44: NBL-DSL | D44: 45T | E44: JAT | F44: Ibadan | G44: Ibadan | H44: Oyo | I44: Onitsha | J44: Anambra | K44: South East | L44: Interstate | N44: Onitsha | O44: Ibadan > Onitsha: 442 | Return Onitsha > Ibadan: 442 | P44: 442 | Q44: 442 | R44: =IF(P44="","",P44+Q44) -> 884 | S44: Estimated (calibrated)
A45: JAT-45T-NBL-DSL-JUMBO | B45: JUMBO | C45: NBL-DSL | D45: 45T | E45: JAT | F45: Ibadan | G45: Ibadan | H45: Oyo | I45: Abakaliki | J45: Ebonyi | K45: South East | L45: Interstate | N45: Abakaliki | O45: Ibadan > Abakaliki: 631 | Return Abakaliki > Ibadan: 631 | P45: 631 | Q45: 631 | R45: =IF(P45="","",P45+Q45) -> 1262 | S45: Estimated (calibrated)
A46: JAT-45T-NBL-DSL-JUMBO | B46: JUMBO | C46: NBL-DSL | D46: 45T | E46: JAT | F46: Ibadan | G46: Ibadan | H46: Oyo | I46: Otukpo | J46: Benue | K46: North Central | L46: Interstate | N46: Otukpo | O46: Ibadan > Otukpo: 655 | Return Otukpo > Ibadan: 655 | P46: 655 | Q46: 655 | R46: =IF(P46="","",P46+Q46) -> 1310 | S46: Estimated (calibrated)
A47: Givanas-45T-NBL-DSL-JUMBO | B47: JUMBO | C47: NBL-DSL | D47: 45T | E47: Givanas | F47: Lagos | G47: Amuwo Odofin | H47: Lagos | I47: Onitsha | J47: Anambra | K47: South East | L47: Interstate | N47: Onitsha | O47: Amuwo Odofin > Onitsha: 483 | Return Onitsha > Amuwo Odofin: 483 | P47: 483 | Q47: 483 | R47: =IF(P47="","",P47+Q47) -> 966 | S47: Estimated (calibrated)
A48: Givanas-45T-NBL-DSL-JUMBO | B48: JUMBO | C48: NBL-DSL | D48: 45T | E48: Givanas | F48: Lagos | G48: Amuwo Odofin | H48: Lagos | I48: Kano | J48: Kano | K48: North West | L48: Interstate | N48: Kano | O48: Amuwo Odofin > Kano: 1021 | Return Kano > Amuwo Odofin: 1021 | P48: 1021 | Q48: 1021 | R48: =IF(P48="","",P48+Q48) -> 2042 | S48: Estimated (calibrated)
A49: Givanas-45T-NBL-DSL-JUMBO | B49: JUMBO | C49: NBL-DSL | D49: 45T | E49: Givanas | F49: Lagos | G49: Amuwo Odofin | H49: Lagos | I49: Sokoto | J49: Sokoto | K49: North West | L49: Interstate | N49: Sokoto | O49: Amuwo Odofin > Sokoto: 928 | Return Sokoto > Amuwo Odofin: 928 | P49: 928 | Q49: 928 | R49: =IF(P49="","",P49+Q49) -> 1856 | S49: Estimated (calibrated)
A50: JAMARA-30T-NBL-DSL-JUMBO | B50: JUMBO | C50: NBL-DSL | D50: 30T | E50: JAMARA | F50: Lagos | G50: JMG Gbagada | H50: Lagos | I50: Port Harcourt | J50: Rivers | K50: South South | L50: Interstate | N50: Port Harcourt | O50: JMG Gbagada > Port Harcourt: 603 | Return Port Harcourt > JMG Gbagada: 603 | P50: 603 | Q50: 603 | R50: =IF(P50="","",P50+Q50) -> 1206 | S50: Estimated (calibrated)
A51: JAMARA-30T-NBL-DSL-JUMBO | B51: JUMBO | C51: NBL-DSL | D51: 30T | E51: JAMARA | F51: Lagos | G51: JMG Gbagada | H51: Lagos | I51: Abuja | J51: FCT | K51: North Central | L51: Interstate | N51: Abuja | O51: JMG Gbagada > Abuja: 740 | Return Abuja > JMG Gbagada: 740 | P51: 740 | Q51: 740 | R51: =IF(P51="","",P51+Q51) -> 1480 | S51: Road-routed (OpenStreetMap)
A52: JAMARA-30T-NBL-DSL-JUMBO | B52: JUMBO | C52: NBL-DSL | D52: 30T | E52: JAMARA | F52: Lagos | G52: JMG Gbagada | H52: Lagos | I52: Kano | J52: Kano | K52: North West | L52: Interstate | N52: Kano | O52: JMG Gbagada > Kano: 984 | Return Kano > JMG Gbagada: 984 | P52: 984 | Q52: 984 | R52: =IF(P52="","",P52+Q52) -> 1968 | S52: Road-routed (OpenStreetMap)
... A67: Mega Manu-45T-NBL-DSL-JUMBO | B67: JUMBO | C67: NBL-DSL | D67: 45T | E67: Mega Manu | F67: Lagos | G67: Apapa | H67: Lagos | I67: Kaduna | J67: Kaduna | K67: North West | L67: Interstate | N67: Kaduna | O67: Apapa > Kaduna: 774 | Return Kaduna > Apapa: 774 | P67: 774 | Q67: 774 | R67: =IF(P67="","",P67+Q67) -> 1548 | S67: Estimated (calibrated)
A68: Mega Manu-Local-30T-NBL-DSL-JUMBO | B68: JUMBO | C68: NBL-DSL | D68: 30T | E68: Mega Manu-Local | F68: Lagos | G68: Apapa | H68: Lagos | I68: Agbara | J68: Ogun | K68: South West | L68: Interstate | M68: Ojo–Badagry | N68: Agbara | O68: Apapa > Agbara: 43 | Return Agbara > Apapa: 43 | P68: 43 | Q68: 43 | R68: =IF(P68="","",P68+Q68) -> 86 | S68: Estimated (calibrated)
A69: Mega Manu-Local-30T-NBL-DSL-JUMBO | B69: JUMBO | C69: NBL-DSL | D69: 30T | E69: Mega Manu-Local | F69: Lagos | G69: Apapa | H69: Lagos | I69: Amuwo Odofin | J69: Lagos | K69: South West | L69: Internal (within state) | M69: Mainland | N69: Amuwo Odofin | O69: Apapa > Amuwo Odofin: 10 | Return Amuwo Odofin > Apapa: 10 | P69: 10 | Q69: 10 | R69: =IF(P69="","",P69+Q69) -> 20 | S69: Estimated (calibrated)
A70: Mega Manu-Local-30T-NBL-DSL-JUMBO | B70: JUMBO | C70: NBL-DSL | D70: 30T | E70: Mega Manu-Local | F70: Lagos | G70: Apapa | H70: Lagos | I70: Isolo | J70: Lagos | K70: South West | L70: Internal (within state) | M70: Mainland | N70: Isolo | O70: Apapa > Isolo: 15 | Return Isolo > Apapa: 15 | P70: 15 | Q70: 15 | R70: =IF(P70="","",P70+Q70) -> 30 | S70: Estimated (calibrated)
A71: Mega Manu-Local-30T-NBL-DSL-JUMBO | B71: JUMBO | C71: NBL-DSL | D71: 30T | E71: Mega Manu-Local | F71: Lagos | G71: Apapa | H71: Lagos | I71: Ibadan | J71: Oyo | K71: South West | L71: Interstate | N71: Ibadan | O71: Apapa > Ibadan: 156 | Return Ibadan > Apapa: 156 | P71: 156 | Q71: 156 | R71: =IF(P71="","",P71+Q71) -> 312 | S71: Estimated (calibrated)
A72: Mega Manu-Local-30T-NBL-DSL-JUMBO | B72: JUMBO | C72: NBL-DSL | D72: 30T | E72: Mega Manu-Local | F72: Lagos | G72: Apapa | H72: Lagos | I72: Sango Ota | J72: Ogun | K72: South West | L72: Interstate | N72: Sango Ota | O72: Apapa > Sango Ota: 42 | Return Sango Ota > Apapa: 42 | P72: 42 | Q72: 42 | R72: =IF(P72="","",P72+Q72) -> 84 | S72: Estimated (calibrated)
A73: Mega Manu-Local-30T-NBL-DSL-JUMBO | B73: JUMBO | C73: NBL-DSL | D73: 30T | E73: Mega Manu-Local | F73: Lagos | G73: Apapa | H73: Lagos | I73: Matori | J73: Lagos | K73: South West | L73: Internal (within state) | M73: Mainland | N73: Matori | O73: Apapa > Matori: 15 | Return Matori > Apapa: 15 | P73: 15 | Q73: 15 | R73: =IF(P73="","",P73+Q73) -> 30 | S73: Estimated (calibrated)
A74: Mega Manu-Local-30T-NBL-DSL-JUMBO | B74: JUMBO | C74: NBL-DSL | D74: 30T | E74: Mega Manu-Local | F74: Lagos | G74: Apapa | H74: Lagos | I74: Fatai Atere | J74: Lagos | K74: South West | L74: Internal (within state) | M74: Mainland | N74: Fatai Atere | O74: Apapa > Fatai Atere: 12 | Return Fatai Atere > Apapa: 12 | P74: 12 | Q74: 12 | R74: =IF(P74="","",P74+Q74) -> 24 | S74: Estimated (calibrated)
A75: Mega Manu-Local-30T-NBL-DSL-JUMBO | B75: JUMBO | C75: NBL-DSL | D75: 30T | E75: Mega Manu-Local | F75: Lagos | G75: Apapa | H75: Lagos | I75: Igbesa | J75: Ogun | K75: South West | L75: Interstate | N75: Igbesa | O75: Apapa > Igbesa: 39 | Return Igbesa > Apapa: 39 | P75: 39 | Q75: 39 | R75: =IF(P75="","",P75+Q75) -> 78 | S75: Estimated (calibrated)
A76: Mega Manu-Local-30T-NBL-DSL-JUMBO | B76: JUMBO | C76: NBL-DSL | D76: 30T | E76: Mega Manu-Local | F76: Lagos | G76: Apapa | H76: Lagos | I76: Ikeja | J76: Lagos | K76: South West | L76: Internal (within state) | M76: Mainland | N76: Ikeja | O76: Apapa > Ikeja: 23 | Return Ikeja > Apapa: 23 | P76: 23 | Q76: 23 | R76: =IF(P76="","",P76+Q76) -> 46 | S76: Estimated (calibrated)
A77: Mega Manu-Local-30T-NBL-DSL-JUMBO | B77: JUMBO | C77: NBL-DSL | D77: 30T | E77: Mega Manu-Local | F77: Lagos | G77: Apapa | H77: Lagos | I77: Dopemu | J77: Lagos | K77: South West | L77: Internal (within state) | M77: Mainland | N77: Dopemu | O77: Apapa > Dopemu: 27 | Return Dopemu > Apapa: 27 | P77: 27 | Q77: 27 | R77: =IF(P77="","",P77+Q77) -> 54 | S77: Estimated (calibrated)
A78: Mega Manu-Local-30T-NBL-DSL-JUMBO | B78: JUMBO | C78: NBL-DSL | D78: 30T | E78: Mega Manu-Local | F78: Lagos | G78: Apapa | H78: Lagos | I78: Sagamu | J78: Ogun | K78: South West | L78: Interstate | N78: Sagamu | O78: Apapa > Sagamu: 70 | Return Sagamu > Apapa: 70 | P78: 70 | Q78: 70 | R78: =IF(P78="","",P78+Q78) -> 140 | S78: Estimated (calibrated)
A79: Mega Manu-Local-30T-NBL-DSL-JUMBO | B79: JUMBO | C79: NBL-DSL | D79: 30T | E79: Mega Manu-Local | F79: Lagos | G79: Apapa | H79: Lagos | I79: Mowe | J79: Ogun | K79: South West | L79: Interstate | N79: Mowe | O79: Apapa > Mowe: 53 | Return Mowe > Apapa: 53 | P79: 53 | Q79: 53 | R79: =IF(P79="","",P79+Q79) -> 106 | S79: Estimated (calibrated)
...

Sheet Driver Mapping On Each Vehicle 
A1: Asset code | B1: Plate Number | C1: Asset Name | D1: Tonnage | E1: Body Size | F1: HR Registered name | G1: Camanda Driver Name | H1: Staff ID no | I1: Station Officer | J1: Station Officer | K1: Operation Manager
A2: MVEH-000266 | B2: T2404LA | C2: Volswagen Titan Tractor 18-310 Head | D2: 25T | E2: FLAT | F2: ABDULSALAM Adams Araga | G2: Adams Araga | H2: 003455 | I2: AYENI Ebenezer Akintunde | J2: DAODU Timileyin Monday | K2: AJIBADE Afeez Adeyemi
A3: MVEH-000267 | B3: T2486LA | C3: Volswagen Titan Tractor 18-310 Head | D3: 25T | E3: FLAT | F3: ADEMOLA Marcus Adedayo | G3: Ademola Marcus Adedayo | H3: 002752 | I3: AYENI Ebenezer Akintunde | J3: DAODU Timileyin Monday | K3: AJIBADE Afeez Adeyemi
A4: MVEH-000269 | B4: T2490LA | C4: Volswagen Titan Tractor 18-310 Head | D4: 25T | E4: FLAT | F4: OLADOYINBO Olusoji Opeyemi | G4: Opeyemi Soji | H4: 002335 | I4: AYENI Ebenezer Akintunde | J4: DAODU Timileyin Monday | K4: AJIBADE Afeez Adeyemi
A5: MVEH-000271 | B5: T2407LA | C5: Volswagen Titan Tractor 18-310 Head | D5: 25T | E5: FLAT | F5: POPOOLA Akeem Olalekan | G5: Akeem Popoola | H5: 001983 | I5: AYENI Ebenezer Akintunde | J5: DAODU Timileyin Monday | K5: AJIBADE Afeez Adeyemi
A6: MVEH-000273 | B6: T2485LA | C6: Volswagen Titan Tractor 18-310 Head | D6: 30T | E6: FLAT | F6: ABUBAKAR Kamal | G6: Kamal Abubakar | H6: 002344 | I6: AYENI Ebenezer Akintunde | J6: DAODU Timileyin Monday | K6: AJIBADE Afeez Adeyemi
A7: MVEH-000276 | B7: T2412LA | C7: Volswagen Titan Tractor 18-310 Head | D7: 25T | E7: FLAT | F7: Hussien Nemadi | G7: Hussien Nemadi | H7: 002200 | I7: AYENI Ebenezer Akintunde | J7: DAODU Timileyin Monday | K7: AJIBADE Afeez Adeyemi
A8: MVEH-000283 | B8: T2420LA | C8: Volswagen Titan Tractor 18-310 Head | D8: 25T | E8: FLAT | F8: ALI Suleiman Nasiru | G8: Naslr Ali | I8: AYENI Ebenezer Akintunde | J8: DAODU Timileyin Monday | K8: AJIBADE Afeez Adeyemi
A9: MVEH-000326 | B9: EPE531YD | C9: Mercedes Benz Diesel Truck | D9: 15T | E9: TANKER | I9: AYENI Ebenezer Akintunde
A10: MVEH-000130 | B10: T2418LA | C10: Volswagen Titan Tractor 18-310 Head | D10: 25T | E10: FLAT | F10: IHINEGBU Lucky Uche | G10: Lucky Ihinegbu | H10: 000556 | I10: AYENI Ebenezer Akintunde | J10: DAODU Timileyin Monday | K10: AJIBADE Afeez Adeyemi
A11: MVEH-000131 | B11: T2489LA | C11: Volswagen Titan Tractor 18-310 Head | D11: 25T | E11: FLAT | F11: OLASUNKANMI Kabiru Ademola | G11: Ademola Marcus Adedayo | H11: 000828 | I11: AYENI Ebenezer Akintunde | J11: DAODU Timileyin Monday | K11: AJIBADE Afeez Adeyemi
A12: MVEH-000132 | B12: T2421LA | C12: Volswagen Titan Tractor 18-310 Head | D12: 25T | E12: FLAT | F12: AZEEZ Kamoru | G12: Azeez Kamorudeen | H12: 001590 | I12: AYENI Ebenezer Akintunde | J12: DAODU Timileyin Monday | K12: AJIBADE Afeez Adeyemi
A13: MVEH-000142 | B13: T2419LA | C13: Volswagen Titan Tractor 18-310 | D13: 25T | E13: FLAT | F13: OLADOYINBO Olusoji Opeyemi | G13: Opeyemi Soji | H13: 002335 | I13: AYENI Ebenezer Akintunde | J13: DAODU Timileyin Monday | K13: AJIBADE Afeez Adeyemi
A14: MVEH-000143 | B14: T2415LA | C14: Volswagen titan Tractor 18-310 Head (double not yet acquired) | D14: 25T | E14: FLAT | F14: OWOLO James Folorunsho | G14: Owolo James | H14: 000914 | I14: AYENI Ebenezer Akintunde | J14: DAODU Timileyin Monday | K14: AJIBADE Afeez Adeyemi
A15: MVEH-000144 | B15: T2414LA | C15: Volswagen Titan Tractor 18-310 Head | D15: 25T | E15: FLAT | F15: AKINOLA Oluwaseun Samson | G15: Seun Akinola | H15: 000164 | I15: AYENI Ebenezer Akintunde | J15: DAODU Timileyin Monday | K15: AJIBADE Afeez Adeyemi
A16: MVEH-000318 | B16: T5526LA | C16: SINOTRUCK HOWO E7 6X4 TRACTOR .STERLING BANK LEASE | D16: 30T | E16: FLAT | F16: IGWALAH Christopher Maxwell | G16: Maxwell Christopher | H16: 000512 | I16: AYENI Ebenezer Akintunde | J16: DAODU Timileyin Monday | K16: AJIBADE Afeez Adeyemi
A17: MVEH-000320 | B17: T5524LA | C17: SINOTRUCK HOWO 4X2 TRACTOR LHD STERLING BANK LEASE | D17: 30T | E17: 102-30T | F17: ARUWAJOYE Kolawole Tilo | G17: Aruwajoye Tilo | H17: 003254 | I17: AYENI Ebenezer Akintunde | J17: DAODU Timileyin Monday | K17: AJIBADE Afeez Adeyemi
A18: MVEH-000327 | B18: T9943LA | C18: Sino Truck Howo 6x4 | D18: 45T | E18: 102-45T | F18: IBRAHIM Alhaji | G18: Alhaji Ibrahim | H18: 000497 | I18: AYENI Ebenezer Akintunde | J18: DAODU Timileyin Monday | K18: AJIBADE Afeez Adeyemi
